Workbook

Sheet PARAMETRY
A1: Regular Season
A2: Parameter | B2: Coefficient | C2: Source | D2: Note
A3: Intercept | B3: 0.42 | C3: Minitab | D3: konstanta
A4: Home | B4: 0.1706 | C4: Minitab | D4: domácí výhoda
A5: xG_Diff | B5: 0.104 | C5: Minitab | D5: kvalita šancí
A6: PP_Diff | B6: 1.619 | C6: Minitab | D6: přesilovky
A7: Goalie | B7: 4.61 | C7: Minitab | D7: vliv golmana
A8: TeamStrength | B8: 0 | C8: External | D8: baseline týmu
A9: Scale_PP | B9: 0.15 | C9: Manual | D9: škálování PP
A10: Scale_xG | B10: 1 | C10: Manual | D10: škálování xG
A11: Scale_Shots | B11: 0.05 | C11: Manual | D11: škálování Shots

Sheet SERIE_INPUT
A1: Zápas | B1: Home | C1: Quality_Diff | D1: PP_Diff | E1: Goalie | F1: log-odds skóre | G1: LogOdds_MC | H1: Win? | I1: Effective_P_Win
A2: G1 | B2: 1 | C2: =CALC_TEAMS_SEASON!$D$4-CALC_TEAMS_SEASON!$D$5 -> 0.040166667 | D2: =(CALC_TEAMS_SEASON!$F$4-CALC_TEAMS_SEASON!$F$5)*(1+PARAMETRY!#REF!*(CALC_TEAMS_SEASON!$K$4-CALC_TEAMS_SEASON!$K$5)) -> #REF! | E2: =CALC_GOALIES!$K$2 -> 0.01761704 | F2: =PARAMETRY!$B$3+SERIE_INPUT!B2*PARAMETRY!#REF!+SERIE_INPUT!C2*PARAMETRY!#REF!+SERIE_INPUT!D2*PARAMETRY!#REF!*PARAMETRY!#REF!+SERIE_INPUT!E2*PARAMETRY!#REF! -> #REF! | G2: =F2+_xlfn.NORM.INV(RAND(),0,0.35) -> #REF! | H2: =1/(1+EXP(-G2)) -> #REF! | I2: =0.85*H2+0.15*0.5 -> #REF! | J2: =I2 -> #REF!
A3: G2 | B3: 1 | C3: =CALC_TEAMS_SEASON!$D$4-CALC_TEAMS_SEASON!$D$5 -> 0.040166667 | D3: =(CALC_TEAMS_SEASON!$F$4-CALC_TEAMS_SEASON!$F$5)*(1+PARAMETRY!#REF!*(CALC_TEAMS_SEASON!$K$4-CALC_TEAMS_SEASON!$K$5)) -> #REF! | E3: =CALC_GOALIES!$K$2 -> 0.01761704 | F3: =PARAMETRY!$B$3+SERIE_INPUT!B3*PARAMETRY!#REF!+SERIE_INPUT!C3*PARAMETRY!#REF!+SERIE_INPUT!D3*PARAMETRY!#REF!*PARAMETRY!#REF!+SERIE_INPUT!E3*PARAMETRY!#REF! -> #REF! | G3: =F3+_xlfn.NORM.INV(RAND(),0,0.35) -> #REF! | H3: =1/(1+EXP(-G3)) -> #REF! | I3: =0.85*H3+0.15*0.5 -> #REF! | J3: =I3 -> #REF!
A4: G3 | B4: 0 | C4: =CALC_TEAMS_SEASON!$D$4-CALC_TEAMS_SEASON!$D$5 -> 0.040166667 | D4: =(CALC_TEAMS_SEASON!$F$4-CALC_TEAMS_SEASON!$F$5)*(1+PARAMETRY!#REF!*(CALC_TEAMS_SEASON!$K$4-CALC_TEAMS_SEASON!$K$5)) -> #REF! | E4: =CALC_GOALIES!$K$2 -> 0.01761704 | F4: =PARAMETRY!$B$3+SERIE_INPUT!B4*PARAMETRY!#REF!+SERIE_INPUT!C4*PARAMETRY!#REF!+SERIE_INPUT!D4*PARAMETRY!#REF!*PARAMETRY!#REF!+SERIE_INPUT!E4*PARAMETRY!#REF! -> #REF! | G4: =F4+_xlfn.NORM.INV(RAND(),0,0.35) -> #REF! | H4: =1/(1+EXP(-G4)) -> #REF! | I4: =0.85*H4+0.15*0.5 -> #REF! | J4: =I4 -> #REF!
A5: G4 | B5: 0 | C5: =CALC_TEAMS_SEASON!$D$4-CALC_TEAMS_SEASON!$D$5 -> 0.040166667 | D5: =(CALC_TEAMS_SEASON!$F$4-CALC_TEAMS_SEASON!$F$5)*(1+PARAMETRY!#REF!*(CALC_TEAMS_SEASON!$K$4-CALC_TEAMS_SEASON!$K$5)) -> #REF! | E5: =CALC_GOALIES!$K$2 -> 0.01761704 | F5: =PARAMETRY!$B$3+SERIE_INPUT!B5*PARAMETRY!#REF!+SERIE_INPUT!C5*PARAMETRY!#REF!+SERIE_INPUT!D5*PARAMETRY!#REF!*PARAMETRY!#REF!+SERIE_INPUT!E5*PARAMETRY!#REF! -> #REF! | G5: =F5+_xlfn.NORM.INV(RAND(),0,0.35) -> #REF! | H5: =1/(1+EXP(-G5)) -> #REF! | I5: =0.85*H5+0.15*0.5 -> #REF! | J5: =I5 -> #REF!
A6: G5 | B6: 1 | C6: =CALC_TEAMS_SEASON!$D$4-CALC_TEAMS_SEASON!$D$5 -> 0.040166667 | D6: =(CALC_TEAMS_SEASON!$F$4-CALC_TEAMS_SEASON!$F$5)*(1+PARAMETRY!#REF!*(CALC_TEAMS_SEASON!$K$4-CALC_TEAMS_SEASON!$K$5)) -> #REF! | E6: =CALC_GOALIES!$K$2 -> 0.01761704 | F6: =PARAMETRY!$B$3+SERIE_INPUT!B6*PARAMETRY!#REF!+SERIE_INPUT!C6*PARAMETRY!#REF!+SERIE_INPUT!D6*PARAMETRY!#REF!*PARAMETRY!#REF!+SERIE_INPUT!E6*PARAMETRY!#REF! -> #REF! | G6: =F6+_xlfn.NORM.INV(RAND(),0,0.35) -> #REF! | H6: =1/(1+EXP(-G6)) -> #REF! | I6: =0.85*H6+0.15*0.5 -> #REF! | J6: =I6 -> #REF!
A7: G6 | B7: 0 | C7: =CALC_TEAMS_SEASON!$D$4-CALC_TEAMS_SEASON!$D$5 -> 0.040166667 | D7: =(CALC_TEAMS_SEASON!$F$4-CALC_TEAMS_SEASON!$F$5)*(1+PARAMETRY!#REF!*(CALC_TEAMS_SEASON!$K$4-CALC_TEAMS_SEASON!$K$5)) -> #REF! | E7: =CALC_GOALIES!$K$2 -> 0.01761704 | F7: =PARAMETRY!$B$3+SERIE_INPUT!B7*PARAMETRY!#REF!+SERIE_INPUT!C7*PARAMETRY!#REF!+SERIE_INPUT!D7*PARAMETRY!#REF!*PARAMETRY!#REF!+SERIE_INPUT!E7*PARAMETRY!#REF! -> #REF! | G7: =F7+_xlfn.NORM.INV(RAND(),0,0.35) -> #REF! | H7: =1/(1+EXP(-G7)) -> #REF! | I7: =0.85*H7+0.15*0.5 -> #REF! | J7: =I7 -> #REF!
A8: G7 | B8: 1 | C8: =CALC_TEAMS_SEASON!$D$4-CALC_TEAMS_SEASON!$D$5 -> 0.040166667 | D8: =(CALC_TEAMS_SEASON!$F$4-CALC_TEAMS_SEASON!$F$5)*(1+PARAMETRY!#REF!*(CALC_TEAMS_SEASON!$K$4-CALC_TEAMS_SEASON!$K$5)) -> #REF! | E8: =CALC_GOALIES!$K$2 -> 0.01761704 | F8: =PARAMETRY!$B$3+SERIE_INPUT!B8*PARAMETRY!#REF!+SERIE_INPUT!C8*PARAMETRY!#REF!+SERIE_INPUT!D8*PARAMETRY!#REF!*PARAMETRY!#REF!+SERIE_INPUT!E8*PARAMETRY!#REF! -> #REF! | G8: =F8+_xlfn.NORM.INV(RAND(),0,0.35) -> #REF! | H8: =1/(1+EXP(-G8)) -> #REF! | I8: =0.85*H8+0.15*0.5 -> #REF! | J8: =I8 -> #REF!

Sheet PREDIKCE_ZAPASU
A1: Match | B1: Home | C1: xG_Diff | D1: PP_Diff | E1: Goalie_rating | F1: Team_Strength | G1: Linear_Score | H1: P_Win

Sheet MODEL_INPUT_PO
A1: Season | B1: Date | C1: Home | D1: xG_Diff_adj | E1: Shots_Diff | F1: Use_xG | G1: Quality_Diff | H1: PP_Diff | I1: Goalie_rating | J1: Team_strength | K1: Game_Weight | L1: Win
A2: =CALC_GAMES_BASE!A106 -> 25/26 | B2: =CALC_GAMES_BASE!B106 -> 45926 | C2: =CALC_GAMES_BASE!E106 -> 1 | D2: =CALC_GAMES_BASE!N106 | E2: =CALC_GAMES_BASE!K106 -> 27 | F2: =IF(D2<>"",1,0) -> 0 | G2: =IF(F2=1, D2, E2*PARAMETRY!B104) -> 0 | H2: =CALC_GAMES_BASE!Q106 - CALC_TEAMS_SEASON!F106 -> 0.2 | I2: =_xlfn.XLOOKUP(CALC_GAMES_BASE!W106, CALC_GOALIES!B:B, CALC_GOALIES!K:K) -> 0.021917995 | K2: =IF(CALC_GAMES_BASE!Z106="RS",1,1.2) -> 1 | L2: =CALC_GAMES_BASE!Y106 -> 1
A3: =CALC_GAMES_BASE!A107 -> 25/26 | B3: =CALC_GAMES_BASE!B107 -> 45926 | C3: =CALC_GAMES_BASE!E107 -> 1 | D3: =CALC_GAMES_BASE!N107 | E3: =CALC_GAMES_BASE!K107 -> 4 | F3: =IF(D3<>"",1,0) -> 0 | G3: =IF(F3=1, D3, E3*PARAMETRY!B105) -> 0 | H3: =CALC_GAMES_BASE!Q107 - CALC_TEAMS_SEASON!F107 -> 0.33333333 | I3: =_xlfn.XLOOKUP(CALC_GAMES_BASE!W107, CALC_GOALIES!B:B, CALC_GOALIES!K:K) -> 0.0044713327 | K3: =IF(CALC_GAMES_BASE!Z107="RS",1,1.2) -> 1 | L3: =CALC_GAMES_BASE!Y107 -> 0
A4: =CALC_GAMES_BASE!A108 -> 25/26 | B4: =CALC_GAMES_BASE!B108 -> 45926 | C4: =CALC_GAMES_BASE!E108 -> 1 | D4: =CALC_GAMES_BASE!N108 | E4: =CALC_GAMES_BASE!K108 -> -10 | F4: =IF(D4<>"",1,0) -> 0 | G4: =IF(F4=1, D4, E4*PARAMETRY!B106) -> 0 | H4: =CALC_GAMES_BASE!Q108 - CALC_TEAMS_SEASON!F108 -> 0.5 | I4: =_xlfn.XLOOKUP(CALC_GAMES_BASE!W108, CALC_GOALIES!B:B, CALC_GOALIES!K:K) -> 0.01761704 | K4: =IF(CALC_GAMES_BASE!Z108="RS",1,1.2) -> 1 | L4: =CALC_GAMES_BASE!Y108 -> 1
A5: =CALC_GAMES_BASE!A109 -> 25/26 | B5: =CALC_GAMES_BASE!B109 -> 45926 | C5: =CALC_GAMES_BASE!E109 -> 0 | D5: =CALC_GAMES_BASE!N109 | E5: =CALC_GAMES_BASE!K109 -> -4 | F5: =IF(D5<>"",1,0) -> 0 | G5: =IF(F5=1, D5, E5*PARAMETRY!B107) -> 0 | H5: =CALC_GAMES_BASE!Q109 - CALC_TEAMS_SEASON!F109 -> 0.33333333 | I5: =_xlfn.XLOOKUP(CALC_GAMES_BASE!W109, CALC_GOALIES!B:B, CALC_GOALIES!K:K) -> 0.0019054879 | K5: =IF(CALC_GAMES_BASE!Z109="RS",1,1.2) -> 1 | L5: =CALC_GAMES_BASE!Y109 -> 1
A6: =CALC_GAMES_BASE!A110 -> 25/26 | B6: =CALC_GAMES_BASE!B110 -> 45928 | C6: =CALC_GAMES_BASE!E110 -> 0 | D6: =CALC_GAMES_BASE!N110 -> 0.8 | E6: =CALC_GAMES_BASE!K110 -> -4 | F6: =IF(D6<>"",1,0) -> 1 | G6: =IF(F6=1, D6, E6*PARAMETRY!B108) -> 0.8 | H6: =CALC_GAMES_BASE!Q110 - CALC_TEAMS_SEASON!F110 -> 0 | I6: =_xlfn.XLOOKUP(CALC_GAMES_BASE!W110, CALC_GOALIES!B:B, CALC_GOALIES!K:K) -> 0.0045881077 | K6: =IF(CALC_GAMES_BASE!Z110="RS",1,1.2) -> 1 | L6: =CALC_GAMES_BASE!Y110 -> 1
A7: =CALC_GAMES_BASE!A111 -> 25/26 | B7: =CALC_GAMES_BASE!B111 -> 45928 | C7: =CALC_GAMES_BASE!E111 -> 1 | D7: =CALC_GAMES_BASE!N111 -> -1.2 | E7: =CALC_GAMES_BASE!K111 -> -14 | F7: =IF(D7<>"",1,0) -> 1 | G7: =IF(F7=1, D7, E7*PARAMETRY!B109) -> -1.2 | H7: =CALC_GAMES_BASE!Q111 - CALC_TEAMS_SEASON!F111 -> 0.33333333 | I7: =_xlfn.XLOOKUP(CALC_GAMES_BASE!W111, CALC_GOALIES!B:B, CALC_GOALIES!K:K) -> 0.013707542 | K7: =IF(CALC_GAMES_BASE!Z111="RS",1,1.2) -> 1 | L7: =CALC_GAMES_BASE!Y111 -> 1
A8: =CALC_GAMES_BASE!A112 -> 25/26 | B8: =CALC_GAMES_BASE!B112 -> 45928 | C8: =CALC_GAMES_BASE!E112 -> 1 | D8: =CALC_GAMES_BASE!N112 -> 2.11 | E8: =CALC_GAMES_BASE!K112 -> 28 | F8: =IF(D8<>"",1,0) -> 1 | G8: =IF(F8=1, D8, E8*PARAMETRY!B110) -> 2.11 | H8: =CALC_GAMES_BASE!Q112 - CALC_TEAMS_SEASON!F112 -> 0.16666667 | I8: =_xlfn.XLOOKUP(CALC_GAMES_BASE!W112, CALC_GOALIES!B:B, CALC_GOALIES!K:K) -> 0.0036462502 | K8: =IF(CALC_GAMES_BASE!Z112="RS",1,1.2) -> 1 | L8: =CALC_GAMES_BASE!Y112 -> 0
A9: =CALC_GAMES_BASE!A113 -> 25/26 | B9: =CALC_GAMES_BASE!B113 -> 45928 | C9: =CALC_GAMES_BASE!E113 -> 1 | D9: =CALC_GAMES_BASE!N113 -> -0.8 | E9: =CALC_GAMES_BASE!K113 -> 3 | F9: =IF(D9<>"",1,0) -> 1 | G9: =IF(F9=1, D9, E9*PARAMETRY!B111) -> -0.8 | H9: =CALC_GAMES_BASE!Q113 - CALC_TEAMS_SEASON!F113 -> 0 | I9: =_xlfn.XLOOKUP(CALC_GAMES_BASE!W113, CALC_GOALIES!B:B, CALC_GOALIES!K:K) -> -0.0015147095 | K9: =IF(CALC_GAMES_BASE!Z113="RS",1,1.2) -> 1 | L9: =CALC_GAMES_BASE!Y113 -> 0
A10: =CALC_GAMES_BASE!A114 -> 25/26 | B10: =CALC_GAMES_BASE!B114 -> 45928 | C10: =CALC_GAMES_BASE!E114 -> 0 | D10: =CALC_GAMES_BASE!N114 | E10: =CALC_GAMES_BASE!K114 -> 8 | F10: =IF(D10<>"",1,0) -> 0 | G10: =IF(F10=1, D10, E10*PARAMETRY!B112) -> 0 | H10: =CALC_GAMES_BASE!Q114 - CALC_TEAMS_SEASON!F114 -> 0.25 | I10: =_xlfn.XLOOKUP(CALC_GAMES_BASE!W114, CALC_GOALIES!B:B, CALC_GOALIES!K:K) -> 0.0039343342 | K10: =IF(CALC_GAMES_BASE!Z114="RS",1,1.2) -> 1 | L10: =CALC_GAMES_BASE!Y114 -> 1
A11: =CALC_GAMES_BASE!A115 -> 25/26 | B11: =CALC_GAMES_BASE!B115 -> 45928 | C11: =CALC_GAMES_BASE!E115 -> 0 | D11: =CALC_GAMES_BASE!N115 -> 1.2 | E11: =CALC_GAMES_BASE!K115 -> 14 | F11: =IF(D11<>"",1,0) -> 1 | G11: =IF(F11=1, D11, E11*PARAMETRY!B113) -> 1.2 | H11: =CALC_GAMES_BASE!Q115 - CALC_TEAMS_SEASON!F115 -> 0.33333333 | I11: =_xlfn.XLOOKUP(CALC_GAMES_BASE!W115, CALC_GOALIES!B:B, CALC_GOALIES!K:K) -> 0.01246319 | K11: =IF(CALC_GAMES_BASE!Z115="RS",1,1.2) -> 1 | L11: =CALC_GAMES_BASE!Y115 -> 0
A12: =CALC_GAMES_BASE!A116 -> 25/26 | B12: =CALC_GAMES_BASE!B116 -> 45928 | C12: =CALC_GAMES_BASE!E116 -> 0 | D12: =CALC_GAMES_BASE!N116 | E12: =CALC_GAMES_BASE!K116 -> -4 | F12: =IF(D12<>"",1,0) -> 0 | G12: =IF(F12=1, D12, E12*PARAMETRY!B114) -> 0 | H12: =CALC_GAMES_BASE!Q116 - CALC_TEAMS_SEASON!F116 -> 0.14285714 | I12: =_xlfn.XLOOKUP(CALC_GAMES_BASE!W116, CALC_GOALIES!B:B, CALC_GOALIES!K:K) -> 0.01224281 | K12: =IF(CALC_GAMES_BASE!Z116="RS",1,1.2) -> 1 | L12: =CALC_GAMES_BASE!Y116 -> 0
A13: =CALC_GAMES_BASE!A117 -> 25/26 | B13: =CALC_GAMES_BASE!B117 -> 45928 | C13: =CALC_GAMES_BASE!E117 -> 0 | D13: =CALC_GAMES_BASE!N117 -> -2.11 | E13: =CALC_GAMES_BASE!K117 -> -28 | F13: =IF(D13<>"",1,0) -> 1 | G13: =IF(F13=1, D13, E13*PARAMETRY!B115) -> -2.11 | H13: =CALC_GAMES_BASE!Q117 - CALC_TEAMS_SEASON!F117 -> 0 | I13: =_xlfn.XLOOKUP(CALC_GAMES_BASE!W117, CALC_GOALIES!B:B, CALC_GOALIES!K:K) -> 0.012275709 | K13: =IF(CALC_GAMES_BASE!Z117="RS",1,1.2) -> 1 | L13: =CALC_GAMES_BASE!Y117 -> 1
... A32: =CALC_GAMES_BASE!A136 -> 25/26 | B32: =CALC_GAMES_BASE!B136 -> 45930 | C32: =CALC_GAMES_BASE!E136 -> 0 | D32: =CALC_GAMES_BASE!N136 -> 0.28 | E32: =CALC_GAMES_BASE!K136 -> -7 | F32: =IF(D32<>"",1,0) -> 1 | G32: =IF(F32=1, D32, E32*PARAMETRY!B134) -> 0.28 | H32: =CALC_GAMES_BASE!Q136 - CALC_TEAMS_SEASON!F136 -> 0 | I32: =_xlfn.XLOOKUP(CALC_GAMES_BASE!W136, CALC_GOALIES!B:B, CALC_GOALIES!K:K) -> -0.0014856766 | K32: =IF(CALC_GAMES_BASE!Z136="RS",1,1.2) -> 1 | L32: =CALC_GAMES_BASE!Y136 -> 1

Sheet MODEL_INPUT
A1: Season | B1: Date | C1: Team | D1: Opponent | E1: Home | F1: xG_Diff_adj | G1: Shots_Diff | H1: Use_xG | I1: Quality_Diff | J1: PP_Diff | K1: Goalie_rating | L1: Team_strength | M1: Game_Weight | N1: Win
A2: =CALC_GAMES_BASE!A2 -> 25/26 | B2: =CALC_GAMES_BASE!B2 -> 45909 | C2: =CALC_GAMES_BASE!C2 -> SPA | D2: =CALC_GAMES_BASE!D2 -> CEB | E2: =CALC_GAMES_BASE!E2 -> 0 | F2: =CALC_GAMES_BASE!N2 -> 0.61 | G2: =CALC_GAMES_BASE!K2 -> -2 | H2: =IF(F2<>"",1,0) -> 1 | I2: =IF(H2=1, F2, G2*PARAMETRY!$B$11) -> 0.61 | J2: =CALC_GAMES_BASE!U2-CALC_GAMES_BASE!V2 -> 0.090390859 | K2: =_xlfn.XLOOKUP(CALC_GAMES_BASE!W2, CALC_GOALIES!B:B, CALC_GOALIES!K:K) -> -0.010634669 | L2: =_xlfn.XLOOKUP(C2,CALC_TEAMS_SEASON!B:B,CALC_TEAMS_SEASON!L:L) -> 0.064376751 | M2: =IF(CALC_GAMES_BASE!Z2="RS",1,1.2) -> 1 | N2: =CALC_GAMES_BASE!Y2 -> 1
A3: =CALC_GAMES_BASE!A3 -> 25/26 | B3: =CALC_GAMES_BASE!B3 -> 45909 | C3: =CALC_GAMES_BASE!C3 -> CEB | D3: =CALC_GAMES_BASE!D3 -> SPA | E3: =CALC_GAMES_BASE!E3 -> 1 | F3: =CALC_GAMES_BASE!N3 -> -0.61 | G3: =CALC_GAMES_BASE!K3 -> 2 | H3: =IF(F3<>"",1,0) -> 1 | I3: =IF(H3=1, F3, G3*PARAMETRY!$B$11) -> -0.61 | J3: =CALC_GAMES_BASE!U3-CALC_GAMES_BASE!V3 -> -0.090390859 | K3: =_xlfn.XLOOKUP(CALC_GAMES_BASE!W3, CALC_GOALIES!B:B, CALC_GOALIES!K:K) -> -0.01372632 | L3: =_xlfn.XLOOKUP(C3,CALC_TEAMS_SEASON!B:B,CALC_TEAMS_SEASON!L:L) -> -0.24978011 | M3: =IF(CALC_GAMES_BASE!Z3="RS",1,1.2) -> 1 | N3: =CALC_GAMES_BASE!Y3 -> 0
A4: =CALC_GAMES_BASE!A4 -> 25/26 | B4: =CALC_GAMES_BASE!B4 -> 45910 | C4: =CALC_GAMES_BASE!C4 -> PCE | D4: =CALC_GAMES_BASE!D4 -> MHK | E4: =CALC_GAMES_BASE!E4 -> 1 | F4: =CALC_GAMES_BASE!N4 | G4: =CALC_GAMES_BASE!K4 -> -4 | H4: =IF(F4<>"",1,0) -> 0 | I4: =IF(H4=1, F4, G4*PARAMETRY!$B$11) -> -0.2 | J4: =CALC_GAMES_BASE!U4-CALC_GAMES_BASE!V4 -> 0.061126374 | K4: =_xlfn.XLOOKUP(CALC_GAMES_BASE!W4, CALC_GOALIES!B:B, CALC_GOALIES!K:K) -> 0.0045881077 | L4: =_xlfn.XLOOKUP(C4,CALC_TEAMS_SEASON!B:B,CALC_TEAMS_SEASON!L:L) -> 0.62437675 | M4: =IF(CALC_GAMES_BASE!Z4="RS",1,1.2) -> 1 | N4: =CALC_GAMES_BASE!Y4 -> 1
A5: =CALC_GAMES_BASE!A5 -> 25/26 | B5: =CALC_GAMES_BASE!B5 -> 45910 | C5: =CALC_GAMES_BASE!C5 -> TRI | D5: =CALC_GAMES_BASE!D5 -> OLO | E5: =CALC_GAMES_BASE!E5 -> 1 | F5: =CALC_GAMES_BASE!N5 -> -0.5 | G5: =CALC_GAMES_BASE!K5 -> 8 | H5: =IF(F5<>"",1,0) -> 1 | I5: =IF(H5=1, F5, G5*PARAMETRY!$B$11) -> -0.5 | J5: =CALC_GAMES_BASE!U5-CALC_GAMES_BASE!V5 -> 0.024481074 | K5: =_xlfn.XLOOKUP(CALC_GAMES_BASE!W5, CALC_GOALIES!B:B, CALC_GOALIES!K:K) -> -0.019657017 | L5: =_xlfn.XLOOKUP(C5,CALC_TEAMS_SEASON!B:B,CALC_TEAMS_SEASON!L:L) -> 0.10805322 | M5: =IF(CALC_GAMES_BASE!Z5="RS",1,1.2) -> 1 | N5: =CALC_GAMES_BASE!Y5 -> 1
A6: =CALC_GAMES_BASE!A6 -> 25/26 | B6: =CALC_GAMES_BASE!B6 -> 45910 | C6: =CALC_GAMES_BASE!C6 -> KOM | D6: =CALC_GAMES_BASE!D6 -> LIT | E6: =CALC_GAMES_BASE!E6 -> 1 | F6: =CALC_GAMES_BASE!N6 | G6: =CALC_GAMES_BASE!K6 -> 14 | H6: =IF(F6<>"",1,0) -> 0 | I6: =IF(H6=1, F6, G6*PARAMETRY!$B$11) -> 0.7 | J6: =CALC_GAMES_BASE!U6-CALC_GAMES_BASE!V6 -> 0.042696886 | K6: =_xlfn.XLOOKUP(CALC_GAMES_BASE!W6, CALC_GOALIES!B:B, CALC_GOALIES!K:K) -> -0.0015147095 | L6: =_xlfn.XLOOKUP(C6,CALC_TEAMS_SEASON!B:B,CALC_TEAMS_SEASON!L:L) -> -0.37268207 | M6: =IF(CALC_GAMES_BASE!Z6="RS",1,1.2) -> 1 | N6: =CALC_GAMES_BASE!Y6 -> 1
A7: =CALC_GAMES_BASE!A7 -> 25/26 | B7: =CALC_GAMES_BASE!B7 -> 45910 | C7: =CALC_GAMES_BASE!C7 -> KLA | D7: =CALC_GAMES_BASE!D7 -> MBL | E7: =CALC_GAMES_BASE!E7 -> 1 | F7: =CALC_GAMES_BASE!N7 | G7: =CALC_GAMES_BASE!K7 -> 13 | H7: =IF(F7<>"",1,0) -> 0 | I7: =IF(H7=1, F7, G7*PARAMETRY!$B$11) -> 0.65 | J7: =CALC_GAMES_BASE!U7-CALC_GAMES_BASE!V7 -> 0.012934982 | K7: =_xlfn.XLOOKUP(CALC_GAMES_BASE!W7, CALC_GOALIES!B:B, CALC_GOALIES!K:K) -> 0.01246319 | L7: =_xlfn.XLOOKUP(C7,CALC_TEAMS_SEASON!B:B,CALC_TEAMS_SEASON!L:L) -> -0.19819678 | M7: =IF(CALC_GAMES_BASE!Z7="RS",1,1.2) -> 1 | N7: =CALC_GAMES_BASE!Y7 -> 0
A8: =CALC_GAMES_BASE!A8 -> 25/26 | B8: =CALC_GAMES_BASE!B8 -> 45910 | C8: =CALC_GAMES_BASE!C8 -> KVA | D8: =CALC_GAMES_BASE!D8 -> VIT | E8: =CALC_GAMES_BASE!E8 -> 1 | F8: =CALC_GAMES_BASE!N8 | G8: =CALC_GAMES_BASE!K8 -> 7 | H8: =IF(F8<>"",1,0) -> 0 | I8: =IF(H8=1, F8, G8*PARAMETRY!$B$11) -> 0.35 | J8: =CALC_GAMES_BASE!U8-CALC_GAMES_BASE!V8 -> 0.0040216728 | K8: =_xlfn.XLOOKUP(CALC_GAMES_BASE!W8, CALC_GOALIES!B:B, CALC_GOALIES!K:K) -> -0.022629454 | L8: =_xlfn.XLOOKUP(C8,CALC_TEAMS_SEASON!B:B,CALC_TEAMS_SEASON!L:L) -> -0.28757178 | M8: =IF(CALC_GAMES_BASE!Z8="RS",1,1.2) -> 1 | N8: =CALC_GAMES_BASE!Y8 -> 0
A9: =CALC_GAMES_BASE!A9 -> 25/26 | B9: =CALC_GAMES_BASE!B9 -> 45910 | C9: =CALC_GAMES_BASE!C9 -> LIB | D9: =CALC_GAMES_BASE!D9 -> PLZ | E9: =CALC_GAMES_BASE!E9 -> 1 | F9: =CALC_GAMES_BASE!N9 | G9: =CALC_GAMES_BASE!K9 -> -1 | H9: =IF(F9<>"",1,0) -> 0 | I9: =IF(H9=1, F9, G9*PARAMETRY!$B$11) -> -0.05 | J9: =CALC_GAMES_BASE!U9-CALC_GAMES_BASE!V9 -> -0.032638889 | K9: =_xlfn.XLOOKUP(CALC_GAMES_BASE!W9, CALC_GOALIES!B:B, CALC_GOALIES!K:K) -> 0.012275709 | L9: =_xlfn.XLOOKUP(C9,CALC_TEAMS_SEASON!B:B,CALC_TEAMS_SEASON!L:L) -> 0.22367822 | M9: =IF(CALC_GAMES_BASE!Z9="RS",1,1.2) -> 1 | N9: =CALC_GAMES_BASE!Y9 -> 0
A10: =CALC_GAMES_BASE!A10 -> 25/26 | B10: =CALC_GAMES_BASE!B10 -> 45910 | C10: =CALC_GAMES_BASE!C10 -> LIT | D10: =CALC_GAMES_BASE!D10 -> KOM | E10: =CALC_GAMES_BASE!E10 -> 0 | F10: =CALC_GAMES_BASE!N10 | G10: =CALC_GAMES_BASE!K10 -> -14 | H10: =IF(F10<>"",1,0) -> 0 | I10: =IF(H10=1, F10, G10*PARAMETRY!$B$11) -> -0.7 | J10: =CALC_GAMES_BASE!U10-CALC_GAMES_BASE!V10 -> -0.042696886 | K10: =_xlfn.XLOOKUP(CALC_GAMES_BASE!W10, CALC_GOALIES!B:B, CALC_GOALIES!K:K) -> -0.0049010889 | L10: =_xlfn.XLOOKUP(C10,CALC_TEAMS_SEASON!B:B,CALC_TEAMS_SEASON!L:L) -> -1.4784468 | M10: =IF(CALC_GAMES_BASE!Z10="RS",1,1.2) -> 1 | N10: =CALC_GAMES_BASE!Y10 -> 0
A11: =CALC_GAMES_BASE!A11 -> 25/26 | B11: =CALC_GAMES_BASE!B11 -> 45910 | C11: =CALC_GAMES_BASE!C11 -> MBL | D11: =CALC_GAMES_BASE!D11 -> KLA | E11: =CALC_GAMES_BASE!E11 -> 0 | F11: =CALC_GAMES_BASE!N11 | G11: =CALC_GAMES_BASE!K11 -> -13 | H11: =IF(F11<>"",1,0) -> 0 | I11: =IF(H11=1, F11, G11*PARAMETRY!$B$11) -> -0.65 | J11: =CALC_GAMES_BASE!U11-CALC_GAMES_BASE!V11 -> -0.012934982 | K11: =_xlfn.XLOOKUP(CALC_GAMES_BASE!W11, CALC_GOALIES!B:B, CALC_GOALIES!K:K) -> -0.0044670611 | L11: =_xlfn.XLOOKUP(C11,CALC_TEAMS_SEASON!B:B,CALC_TEAMS_SEASON!L:L) -> -0.89069678 | M11: =IF(CALC_GAMES_BASE!Z11="RS",1,1.2) -> 1 | N11: =CALC_GAMES_BASE!Y11 -> 1
A12: =CALC_GAMES_BASE!A12 -> 25/26 | B12: =CALC_GAMES_BASE!B12 -> 45910 | C12: =CALC_GAMES_BASE!C12 -> MHK | D12: =CALC_GAMES_BASE!D12 -> PCE | E12: =CALC_GAMES_BASE!E12 -> 0 | F12: =CALC_GAMES_BASE!N12 | G12: =CALC_GAMES_BASE!K12 -> 4 | H12: =IF(F12<>"",1,0) -> 0 | I12: =IF(H12=1, F12, G12*PARAMETRY!$B$11) -> 0.2 | J12: =CALC_GAMES_BASE!U12-CALC_GAMES_BASE!V12 -> -0.061126374 | K12: =_xlfn.XLOOKUP(CALC_GAMES_BASE!W12, CALC_GOALIES!B:B, CALC_GOALIES!K:K) -> -0.0640245 | L12: =_xlfn.XLOOKUP(C12,CALC_TEAMS_SEASON!B:B,CALC_TEAMS_SEASON!L:L) -> 0.14821989 | M12: =IF(CALC_GAMES_BASE!Z12="RS",1,1.2) -> 1 | N12: =CALC_GAMES_BASE!Y12 -> 0
A13: =CALC_GAMES_BASE!A13 -> 25/26 | B13: =CALC_GAMES_BASE!B13 -> 45910 | C13: =CALC_GAMES_BASE!C13 -> OLO | D13: =CALC_GAMES_BASE!D13 -> TRI | E13: =CALC_GAMES_BASE!E13 -> 0 | F13: =CALC_GAMES_BASE!N13 -> 0.5 | G13: =CALC_GAMES_BASE!K13 -> -8 | H13: =IF(F13<>"",1,0) -> 1 | I13: =IF(H13=1, F13, G13*PARAMETRY!$B$11) -> 0.5 | J13: =CALC_GAMES_BASE!U13-CALC_GAMES_BASE!V13 -> -0.024481074 | K13: =_xlfn.XLOOKUP(CALC_GAMES_BASE!W13, CALC_GOALIES!B:B, CALC_GOALIES!K:K) -> 0.0044713327 | L13: =_xlfn.XLOOKUP(C13,CALC_TEAMS_SEASON!B:B,CALC_TEAMS_SEASON!L:L) -> -1.0613218 | M13: =IF(CALC_GAMES_BASE!Z13="RS",1,1.2) -> 1 | N13: =CALC_GAMES_BASE!Y13 -> 0
... A731: =CALC_GAMES_BASE!A731 -> 26/27 | B731: =CALC_GAMES_BASE!B731 -> 46160 | C731: =CALC_GAMES_BASE!C731 -> KOM | D731: =CALC_GAMES_BASE!D731 -> PCE | E731: =CALC_GAMES_BASE!E731 -> 0 | F731: =CALC_GAMES_BASE!N731 | G731: =CALC_GAMES_BASE!K731 -> 0 | H731: =IF(F731<>"",1,0) -> 0 | I731: =IF(H731=1, F731, G731*PARAMETRY!$B$11) -> 0 | J731: =CALC_GAMES_BASE!U731-CALC_GAMES_BASE!V731 -> -0.059386447 | K731: =_xlfn.XLOOKUP(CALC_GAMES_BASE!W731, CALC_GOALIES!B:B, CALC_GOALIES!K:K) -> -0.0015147095 | L731: =_xlfn.XLOOKUP(C731,CALC_TEAMS_SEASON!B:B,CALC_TEAMS_SEASON!L:L) -> -0.37268207 | M731: =IF(CALC_GAMES_BASE!Z731="RS",1,1.2) -> 1 | N731: =CALC_GAMES_BASE!Y731 -> 0

Sheet CALC_TEAMS_SEASON
A1: Season | B1: Team | C1: Games | D1: avg_xG_Diff | E1: avg_Shots_Diff | F1: avg_PP_Rate | G1: avg_PK_Rate | H1: avg_Goals_Diff | I1: Team_Strength | J1: Game Type | K1: avg_PP_O | L1: Team_Strength_average | P1: =(AVERAGE(D2:D17))*-1 -> 0.15444678
A2: 25/26 | B2: PCE | C2: =COUNTIFS(CALC_GAMES_BASE!C:C, B2, CALC_GAMES_BASE!A:A, A2,CALC_GAMES_BASE!Z:Z,J2) -> 52 | D2: =AVERAGEIFS(CALC_GAMES_BASE!N:N, CALC_GAMES_BASE!C:C, B2, CALC_GAMES_BASE!A:A, A2,CALC_GAMES_BASE!Z:Z,J2) -> 0.77882353 | E2: =AVERAGEIFS(CALC_GAMES_BASE!K:K, CALC_GAMES_BASE!C:C, B2, CALC_GAMES_BASE!A:A, A2,CALC_GAMES_BASE!Z:Z,J2) -> 8.0384615 | F2: =AVERAGEIFS(CALC_GAMES_BASE!Q:Q, CALC_GAMES_BASE!C:C, B2, CALC_GAMES_BASE!A:A, A2,CALC_GAMES_BASE!Z:Z,J2) -> 0.20297619 | G2: =AVERAGEIFS(CALC_GAMES_BASE!T:T, CALC_GAMES_BASE!C:C, B2, CALC_GAMES_BASE!A:A, A2,CALC_GAMES_BASE!Z:Z,J2) -> 0.87789225 | H2: =AVERAGEIFS(CALC_GAMES_BASE!H:H, CALC_GAMES_BASE!C:C, B2, CALC_GAMES_BASE!A:A, A2,CALC_GAMES_BASE!Z:Z,J2) -> 0.96153846 | I2: =D2*0.6+H2*0.3+E2*0.1 -> 1.5596018 | J2: RS | K2: =AVERAGEIFS(CALC_GAMES_BASE!O:O, CALC_GAMES_BASE!C:C, B2, CALC_GAMES_BASE!A:A, A2,CALC_GAMES_BASE!Z:Z,J2) -> 4.4807692 | L2: =D2-$P$1 -> 0.62437675
A3: 25/26 | B3: LIB | C3: =COUNTIFS(CALC_GAMES_BASE!C:C, B3, CALC_GAMES_BASE!A:A, A3,CALC_GAMES_BASE!Z:Z,J3) -> 52 | D3: =AVERAGEIFS(CALC_GAMES_BASE!N:N, CALC_GAMES_BASE!C:C, B3, CALC_GAMES_BASE!A:A, A3,CALC_GAMES_BASE!Z:Z,J3) -> 0.378125 | E3: =AVERAGEIFS(CALC_GAMES_BASE!K:K, CALC_GAMES_BASE!C:C, B3, CALC_GAMES_BASE!A:A, A3,CALC_GAMES_BASE!Z:Z,J3) -> 5.4230769 | F3: =AVERAGEIFS(CALC_GAMES_BASE!Q:Q, CALC_GAMES_BASE!C:C, B3, CALC_GAMES_BASE!A:A, A3,CALC_GAMES_BASE!Z:Z,J3) -> 0.14377289 | G3: =AVERAGEIFS(CALC_GAMES_BASE!T:T, CALC_GAMES_BASE!C:C, B3, CALC_GAMES_BASE!A:A, A3,CALC_GAMES_BASE!Z:Z,J3) -> 0.87498474 | H3: =AVERAGEIFS(CALC_GAMES_BASE!H:H, CALC_GAMES_BASE!C:C, B3, CALC_GAMES_BASE!A:A, A3,CALC_GAMES_BASE!Z:Z,J3) -> 0.51923077 | I3: =D3*0.6+H3*0.3+E3*0.1 -> 0.92495192 | J3: RS | K3: =AVERAGEIFS(CALC_GAMES_BASE!O:O, CALC_GAMES_BASE!C:C, B3, CALC_GAMES_BASE!A:A, A3,CALC_GAMES_BASE!Z:Z,J3) -> 4.25 | L3: =D3-$P$1 -> 0.22367822
A4: 25/26 | B4: MHK | C4: =COUNTIFS(CALC_GAMES_BASE!C:C, B4, CALC_GAMES_BASE!A:A, A4,CALC_GAMES_BASE!Z:Z,J4) -> 52 | D4: =AVERAGEIFS(CALC_GAMES_BASE!N:N, CALC_GAMES_BASE!C:C, B4, CALC_GAMES_BASE!A:A, A4,CALC_GAMES_BASE!Z:Z,J4) -> 0.30266667 | E4: =AVERAGEIFS(CALC_GAMES_BASE!K:K, CALC_GAMES_BASE!C:C, B4, CALC_GAMES_BASE!A:A, A4,CALC_GAMES_BASE!Z:Z,J4) -> 1.6923077 | F4: =AVERAGEIFS(CALC_GAMES_BASE!Q:Q, CALC_GAMES_BASE!C:C, B4, CALC_GAMES_BASE!A:A, A4,CALC_GAMES_BASE!Z:Z,J4) -> 0.14184982 | G4: =AVERAGEIFS(CALC_GAMES_BASE!T:T, CALC_GAMES_BASE!C:C, B4, CALC_GAMES_BASE!A:A, A4,CALC_GAMES_BASE!Z:Z,J4) -> 0.86630037 | H4: =AVERAGEIFS(CALC_GAMES_BASE!H:H, CALC_GAMES_BASE!C:C, B4, CALC_GAMES_BASE!A:A, A4,CALC_GAMES_BASE!Z:Z,J4) -> 0.40384615 | I4: =D4*0.6+H4*0.3+E4*0.1 -> 0.47198462 | J4: RS | K4: =AVERAGEIFS(CALC_GAMES_BASE!O:O, CALC_GAMES_BASE!C:C, B4, CALC_GAMES_BASE!A:A, A4,CALC_GAMES_BASE!Z:Z,J4) -> 4.0192308 | L4: =D4-$P$1 -> 0.14821989
A5: 25/26 | B5: TRI | C5: =COUNTIFS(CALC_GAMES_BASE!C:C, B5, CALC_GAMES_BASE!A:A, A5,CALC_GAMES_BASE!Z:Z,J5) -> 52 | D5: =AVERAGEIFS(CALC_GAMES_BASE!N:N, CALC_GAMES_BASE!C:C, B5, CALC_GAMES_BASE!A:A, A5,CALC_GAMES_BASE!Z:Z,J5) -> 0.2625 | E5: =AVERAGEIFS(CALC_GAMES_BASE!K:K, CALC_GAMES_BASE!C:C, B5, CALC_GAMES_BASE!A:A, A5,CALC_GAMES_BASE!Z:Z,J5) -> 0.36538462 | F5: =AVERAGEIFS(CALC_GAMES_BASE!Q:Q, CALC_GAMES_BASE!C:C, B5, CALC_GAMES_BASE!A:A, A5,CALC_GAMES_BASE!Z:Z,J5) -> 0.17437424 | G5: =AVERAGEIFS(CALC_GAMES_BASE!T:T, CALC_GAMES_BASE!C:C, B5, CALC_GAMES_BASE!A:A, A5,CALC_GAMES_BASE!Z:Z,J5) -> 0.86165293 | H5: =AVERAGEIFS(CALC_GAMES_BASE!H:H, CALC_GAMES_BASE!C:C, B5, CALC_GAMES_BASE!A:A, A5,CALC_GAMES_BASE!Z:Z,J5) -> 0.32692308 | I5: =D5*0.6+H5*0.3+E5*0.1 -> 0.29211538 | J5: RS | K5: =AVERAGEIFS(CALC_GAMES_BASE!O:O, CALC_GAMES_BASE!C:C, B5, CALC_GAMES_BASE!A:A, A5,CALC_GAMES_BASE!Z:Z,J5) -> 3.8846154 | L5: =D5-$P$1 -> 0.10805322
A6: 25/26 | B6: PLZ | C6: =COUNTIFS(CALC_GAMES_BASE!C:C, B6, CALC_GAMES_BASE!A:A, A6,CALC_GAMES_BASE!Z:Z,J6) -> 52 | D6: =AVERAGEIFS(CALC_GAMES_BASE!N:N, CALC_GAMES_BASE!C:C, B6, CALC_GAMES_BASE!A:A, A6,CALC_GAMES_BASE!Z:Z,J6) -> 0.228125 | E6: =AVERAGEIFS(CALC_GAMES_BASE!K:K, CALC_GAMES_BASE!C:C, B6, CALC_GAMES_BASE!A:A, A6,CALC_GAMES_BASE!Z:Z,J6) -> 3.2692308 | F6: =AVERAGEIFS(CALC_GAMES_BASE!Q:Q, CALC_GAMES_BASE!C:C, B6, CALC_GAMES_BASE!A:A, A6,CALC_GAMES_BASE!Z:Z,J6) -> 0.17641178 | G6: =AVERAGEIFS(CALC_GAMES_BASE!T:T, CALC_GAMES_BASE!C:C, B6, CALC_GAMES_BASE!A:A, A6,CALC_GAMES_BASE!Z:Z,J6) -> 0.87712912 | H6: =AVERAGEIFS(CALC_GAMES_BASE!H:H, CALC_GAMES_BASE!C:C, B6, CALC_GAMES_BASE!A:A, A6,CALC_GAMES_BASE!Z:Z,J6) -> 0.73076923 | I6: =D6*0.6+H6*0.3+E6*0.1 -> 0.68302885 | J6: RS | K6: =AVERAGEIFS(CALC_GAMES_BASE!O:O, CALC_GAMES_BASE!C:C, B6, CALC_GAMES_BASE!A:A, A6,CALC_GAMES_BASE!Z:Z,J6) -> 4.1730769 | L6: =D6-$P$1 -> 0.073678221
A7: 25/26 | B7: SPA | C7: =COUNTIFS(CALC_GAMES_BASE!C:C, B7, CALC_GAMES_BASE!A:A, A7,CALC_GAMES_BASE!Z:Z,J7) -> 52 | D7: =AVERAGEIFS(CALC_GAMES_BASE!N:N, CALC_GAMES_BASE!C:C, B7, CALC_GAMES_BASE!A:A, A7,CALC_GAMES_BASE!Z:Z,J7) -> 0.21882353 | E7: =AVERAGEIFS(CALC_GAMES_BASE!K:K, CALC_GAMES_BASE!C:C, B7, CALC_GAMES_BASE!A:A, A7,CALC_GAMES_BASE!Z:Z,J7) -> 4.8653846 | F7: =AVERAGEIFS(CALC_GAMES_BASE!Q:Q, CALC_GAMES_BASE!C:C, B7, CALC_GAMES_BASE!A:A, A7,CALC_GAMES_BASE!Z:Z,J7) -> 0.2206044 | G7: =AVERAGEIFS(CALC_GAMES_BASE!T:T, CALC_GAMES_BASE!C:C, B7, CALC_GAMES_BASE!A:A, A7,CALC_GAMES_BASE!Z:Z,J7) -> 0.84239164 | H7: =AVERAGEIFS(CALC_GAMES_BASE!H:H, CALC_GAMES_BASE!C:C, B7, CALC_GAMES_BASE!A:A, A7,CALC_GAMES_BASE!Z:Z,J7) -> 0.5 | I7: =D7*0.6+H7*0.3+E7*0.1 -> 0.76783258 | J7: RS | K7: =AVERAGEIFS(CALC_GAMES_BASE!O:O, CALC_GAMES_BASE!C:C, B7, CALC_GAMES_BASE!A:A, A7,CALC_GAMES_BASE!Z:Z,J7) -> 4.4615385 | L7: =D7-$P$1 -> 0.064376751
A8: 25/26 | B8: KLA | C8: =COUNTIFS(CALC_GAMES_BASE!C:C, B8, CALC_GAMES_BASE!A:A, A8,CALC_GAMES_BASE!Z:Z,J8) -> 52 | D8: =AVERAGEIFS(CALC_GAMES_BASE!N:N, CALC_GAMES_BASE!C:C, B8, CALC_GAMES_BASE!A:A, A8,CALC_GAMES_BASE!Z:Z,J8) -> -0.04375 | E8: =AVERAGEIFS(CALC_GAMES_BASE!K:K, CALC_GAMES_BASE!C:C, B8, CALC_GAMES_BASE!A:A, A8,CALC_GAMES_BASE!Z:Z,J8) -> -0.038461538 | F8: =AVERAGEIFS(CALC_GAMES_BASE!Q:Q, CALC_GAMES_BASE!C:C, B8, CALC_GAMES_BASE!A:A, A8,CALC_GAMES_BASE!Z:Z,J8) -> 0.13120421 | G8: =AVERAGEIFS(CALC_GAMES_BASE!T:T, CALC_GAMES_BASE!C:C, B8, CALC_GAMES_BASE!A:A, A8,CALC_GAMES_BASE!Z:Z,J8) -> 0.86549908 | H8: =AVERAGEIFS(CALC_GAMES_BASE!H:H, CALC_GAMES_BASE!C:C, B8, CALC_GAMES_BASE!A:A, A8,CALC_GAMES_BASE!Z:Z,J8) -> -0.15384615 | I8: =D8*0.6+H8*0.3+E8*0.1 -> -0.07625 | J8: RS | K8: =AVERAGEIFS(CALC_GAMES_BASE!O:O, CALC_GAMES_BASE!C:C, B8, CALC_GAMES_BASE!A:A, A8,CALC_GAMES_BASE!Z:Z,J8) -> 4 | L8: =D8-$P$1 -> -0.19819678
A9: 25/26 | B9: CEB | C9: =COUNTIFS(CALC_GAMES_BASE!C:C, B9, CALC_GAMES_BASE!A:A, A9,CALC_GAMES_BASE!Z:Z,J9) -> 52 | D9: =AVERAGEIFS(CALC_GAMES_BASE!N:N, CALC_GAMES_BASE!C:C, B9, CALC_GAMES_BASE!A:A, A9,CALC_GAMES_BASE!Z:Z,J9) -> -0.095333333 | E9: =AVERAGEIFS(CALC_GAMES_BASE!K:K, CALC_GAMES_BASE!C:C, B9, CALC_GAMES_BASE!A:A, A9,CALC_GAMES_BASE!Z:Z,J9) -> 0.48076923 | F9: =AVERAGEIFS(CALC_GAMES_BASE!Q:Q, CALC_GAMES_BASE!C:C, B9, CALC_GAMES_BASE!A:A, A9,CALC_GAMES_BASE!Z:Z,J9) -> 0.13021354 | G9: =AVERAGEIFS(CALC_GAMES_BASE!T:T, CALC_GAMES_BASE!C:C, B9, CALC_GAMES_BASE!A:A, A9,CALC_GAMES_BASE!Z:Z,J9) -> 0.86760531 | H9: =AVERAGEIFS(CALC_GAMES_BASE!H:H, CALC_GAMES_BASE!C:C, B9, CALC_GAMES_BASE!A:A, A9,CALC_GAMES_BASE!Z:Z,J9) -> -0.096153846 | I9: =D9*0.6+H9*0.3+E9*0.1 -> -0.037969231 | J9: RS | K9: =AVERAGEIFS(CALC_GAMES_BASE!O:O, CALC_GAMES_BASE!C:C, B9, CALC_GAMES_BASE!A:A, A9,CALC_GAMES_BASE!Z:Z,J9) -> 4.25 | L9: =D9-$P$1 -> -0.24978011
A10: 25/26 | B10: KVA | C10: =COUNTIFS(CALC_GAMES_BASE!C:C, B10, CALC_GAMES_BASE!A:A, A10,CALC_GAMES_BASE!Z:Z,J10) -> 52 | D10: =AVERAGEIFS(CALC_GAMES_BASE!N:N, CALC_GAMES_BASE!C:C, B10, CALC_GAMES_BASE!A:A, A10,CALC_GAMES_BASE!Z:Z,J10) -> -0.133125 | E10: =AVERAGEIFS(CALC_GAMES_BASE!K:K, CALC_GAMES_BASE!C:C, B10, CALC_GAMES_BASE!A:A, A10,CALC_GAMES_BASE!Z:Z,J10) -> 0.76923077 | F10: =AVERAGEIFS(CALC_GAMES_BASE!Q:Q, CALC_GAMES_BASE!C:C, B10, CALC_GAMES_BASE!A:A, A10,CALC_GAMES_BASE!Z:Z,J10) -> 0.17387057 | G10: =AVERAGEIFS(CALC_GAMES_BASE!T:T, CALC_GAMES_BASE!C:C, B10, CALC_GAMES_BASE!A:A, A10,CALC_GAMES_BASE!Z:Z,J10) -> 0.89864927 | H10: =AVERAGEIFS(CALC_GAMES_BASE!H:H, CALC_GAMES_BASE!C:C, B10, CALC_GAMES_BASE!A:A, A10,CALC_GAMES_BASE!Z:Z,J10) -> 0.15384615 | I10: =D10*0.6+H10*0.3+E10*0.1 -> 0.043201923 | J10: RS | K10: =AVERAGEIFS(CALC_GAMES_BASE!O:O, CALC_GAMES_BASE!C:C, B10, CALC_GAMES_BASE!A:A, A10,CALC_GAMES_BASE!Z:Z,J10) -> 4.3846154 | L10: =D10-$P$1 -> -0.28757178
A11: 25/26 | B11: KOM | C11: =COUNTIFS(CALC_GAMES_BASE!C:C, B11, CALC_GAMES_BASE!A:A, A11,CALC_GAMES_BASE!Z:Z,J11) -> 52 | D11: =AVERAGEIFS(CALC_GAMES_BASE!N:N, CALC_GAMES_BASE!C:C, B11, CALC_GAMES_BASE!A:A, A11,CALC_GAMES_BASE!Z:Z,J11) -> -0.21823529 | E11: =AVERAGEIFS(CALC_GAMES_BASE!K:K, CALC_GAMES_BASE!C:C, B11, CALC_GAMES_BASE!A:A, A11,CALC_GAMES_BASE!Z:Z,J11) -> -0.30769231 | F11: =AVERAGEIFS(CALC_GAMES_BASE!Q:Q, CALC_GAMES_BASE!C:C, B11, CALC_GAMES_BASE!A:A, A11,CALC_GAMES_BASE!Z:Z,J11) -> 0.14358974 | G11: =AVERAGEIFS(CALC_GAMES_BASE!T:T, CALC_GAMES_BASE!C:C, B11, CALC_GAMES_BASE!A:A, A11,CALC_GAMES_BASE!Z:Z,J11) -> 0.81149267 | H11: =AVERAGEIFS(CALC_GAMES_BASE!H:H, CALC_GAMES_BASE!C:C, B11, CALC_GAMES_BASE!A:A, A11,CALC_GAMES_BASE!Z:Z,J11) -> -0.15384615 | I11: =D11*0.6+H11*0.3+E11*0.1 -> -0.20786425 | J11: RS | K11: =AVERAGEIFS(CALC_GAMES_BASE!O:O, CALC_GAMES_BASE!C:C, B11, CALC_GAMES_BASE!A:A, A11,CALC_GAMES_BASE!Z:Z,J11) -> 4.0192308 | L11: =D11-$P$1 -> -0.37268207
A12: 25/26 | B12: MBL | C12: =COUNTIFS(CALC_GAMES_BASE!C:C, B12, CALC_GAMES_BASE!A:A, A12,CALC_GAMES_BASE!Z:Z,J12) -> 52 | D12: =AVERAGEIFS(CALC_GAMES_BASE!N:N, CALC_GAMES_BASE!C:C, B12, CALC_GAMES_BASE!A:A, A12,CALC_GAMES_BASE!Z:Z,J12) -> -0.73625 | E12: =AVERAGEIFS(CALC_GAMES_BASE!K:K, CALC_GAMES_BASE!C:C, B12, CALC_GAMES_BASE!A:A, A12,CALC_GAMES_BASE!Z:Z,J12) -> -2.2307692 | F12: =AVERAGEIFS(CALC_GAMES_BASE!Q:Q, CALC_GAMES_BASE!C:C, B12, CALC_GAMES_BASE!A:A, A12,CALC_GAMES_BASE!Z:Z,J12) -> 0.11826923 | G12: =AVERAGEIFS(CALC_GAMES_BASE!T:T, CALC_GAMES_BASE!C:C, B12, CALC_GAMES_BASE!A:A, A12,CALC_GAMES_BASE!Z:Z,J12) -> 0.80737179 | H12: =AVERAGEIFS(CALC_GAMES_BASE!H:H, CALC_GAMES_BASE!C:C, B12, CALC_GAMES_BASE!A:A, A12,CALC_GAMES_BASE!Z:Z,J12) -> -0.73076923 | I12: =D12*0.6+H12*0.3+E12*0.1 -> -0.88405769 | J12: RS | K12: =AVERAGEIFS(CALC_GAMES_BASE!O:O, CALC_GAMES_BASE!C:C, B12, CALC_GAMES_BASE!A:A, A12,CALC_GAMES_BASE!Z:Z,J12) -> 3.5576923 | L12: =D12-$P$1 -> -0.89069678
A13: 25/26 | B13: VIT | C13: =COUNTIFS(CALC_GAMES_BASE!C:C, B13, CALC_GAMES_BASE!A:A, A13,CALC_GAMES_BASE!Z:Z,J13) -> 52 | D13: =AVERAGEIFS(CALC_GAMES_BASE!N:N, CALC_GAMES_BASE!C:C, B13, CALC_GAMES_BASE!A:A, A13,CALC_GAMES_BASE!Z:Z,J13) -> -0.87375 | E13: =AVERAGEIFS(CALC_GAMES_BASE!K:K, CALC_GAMES_BASE!C:C, B13, CALC_GAMES_BASE!A:A, A13,CALC_GAMES_BASE!Z:Z,J13) -> -7.1923077 | F13: =AVERAGEIFS(CALC_GAMES_BASE!Q:Q, CALC_GAMES_BASE!C:C, B13, CALC_GAMES_BASE!A:A, A13,CALC_GAMES_BASE!Z:Z,J13) -> 0.1698489 | G13: =AVERAGEIFS(CALC_GAMES_BASE!T:T, CALC_GAMES_BASE!C:C, B13, CALC_GAMES_BASE!A:A, A13,CALC_GAMES_BASE!Z:Z,J13) -> 0.79578755 | H13: =AVERAGEIFS(CALC_GAMES_BASE!H:H, CALC_GAMES_BASE!C:C, B13, CALC_GAMES_BASE!A:A, A13,CALC_GAMES_BASE!Z:Z,J13) -> -0.48076923 | I13: =D13*0.6+H13*0.3+E13*0.1 -> -1.3877115 | J13: RS | K13: =AVERAGEIFS(CALC_GAMES_BASE!O:O, CALC_GAMES_BASE!C:C, B13, CALC_GAMES_BASE!A:A, A13,CALC_GAMES_BASE!Z:Z,J13) -> 4 | L13: =D13-$P$1 -> -1.0281968
... A15: 25/26 | B15: LIT | C15: =COUNTIFS(CALC_GAMES_BASE!C:C, B15, CALC_GAMES_BASE!A:A, A15,CALC_GAMES_BASE!Z:Z,J15) -> 52 | D15: =AVERAGEIFS(CALC_GAMES_BASE!N:N, CALC_GAMES_BASE!C:C, B15, CALC_GAMES_BASE!A:A, A15,CALC_GAMES_BASE!Z:Z,J15) -> -1.324 | E15: =AVERAGEIFS(CALC_GAMES_BASE!K:K, CALC_GAMES_BASE!C:C, B15, CALC_GAMES_BASE!A:A, A15,CALC_GAMES_BASE!Z:Z,J15) -> -7.8653846 | F15: =AVERAGEIFS(CALC_GAMES_BASE!Q:Q, CALC_GAMES_BASE!C:C, B15, CALC_GAMES_BASE!A:A, A15,CALC_GAMES_BASE!Z:Z,J15) -> 0.10089286 | G15: =AVERAGEIFS(CALC_GAMES_BASE!T:T, CALC_GAMES_BASE!C:C, B15, CALC_GAMES_BASE!A:A, A15,CALC_GAMES_BASE!Z:Z,J15) -> 0.80388292 | H15: =AVERAGEIFS(CALC_GAMES_BASE!H:H, CALC_GAMES_BASE!C:C, B15, CALC_GAMES_BASE!A:A, A15,CALC_GAMES_BASE!Z:Z,J15) -> -1.2884615 | I15: =D15*0.6+H15*0.3+E15*0.1 -> -1.9674769 | J15: RS | K15: =AVERAGEIFS(CALC_GAMES_BASE!O:O, CALC_GAMES_BASE!C:C, B15, CALC_GAMES_BASE!A:A, A15,CALC_GAMES_BASE!Z:Z,J15) -> 3.8269231 | L15: =D15-$P$1 -> -1.4784468

Sheet CALC_GAMES_BASE
A1: Season | B1: Date | C1: Team | D1: Opponent | E1: Home | F1: Goals_For | G1: Goals_Against | H1: Goals_Diff | I1: Shots_For | J1: Shots_Against | K1: Shots_Diff | L1: xG_For | M1: xG_Against | N1: xG_Diff | O1: PP_O | P1: PP_G | Q1: PP_Rate | R1: PK_O | S1: PK_GA | T1: PK_Rate | U1: PP_Eff | V1: PP_Eff_Opponent | W1: Goalie_Primary | X1: Goalie_SV_Total | Y1: Win | Z1: Game_Type
A2: =RAW_GAMES!A2 -> 25/26 | B2: =RAW_GAMES!B2 -> 45909 | C2: =RAW_GAMES!E2 -> SPA | D2: =RAW_GAMES!F2 -> CEB | E2: =RAW_GAMES!G2 -> 0 | F2: =RAW_GAMES!H2 -> 3 | G2: =RAW_GAMES!I2 -> 2 | H2: =F2-G2 -> 1 | I2: =RAW_GAMES!J2 -> 26 | J2: =RAW_GAMES!K2 -> 28 | K2: =I2-J2 -> -2 | L2: =IF(RAW_GAMES!L2="","",RAW_GAMES!L2) -> 2.3 | M2: =IF(RAW_GAMES!M2="","",RAW_GAMES!M2) -> 1.69 | N2: =IF(L2="","",L2-M2) -> 0.61 | O2: =RAW_GAMES!O2 -> 2 | P2: =RAW_GAMES!N2 -> 0 | Q2: =IF(O2>0,P2/O2,0) -> 0 | R2: =RAW_GAMES!Q2 -> 3 | S2: =RAW_GAMES!P2 -> 0 | T2: =IF(R2>0, 1-(S2/R2),1) -> 1 | U2: =_xlfn.XLOOKUP(C2, CALC_TEAMS_SEASON!B:B, CALC_TEAMS_SEASON!F:F) -> 0.2206044 | V2: =_xlfn.XLOOKUP(D2, CALC_TEAMS_SEASON!B:B, CALC_TEAMS_SEASON!F:F) -> 0.13021354 | W2: =RAW_GAMES!R2 -> Kořenář | X2: =RAW_GAMES!S2 -> 26 | Y2: =IF(F2>G2,1,0) -> 1 | Z2: =RAW_GAMES!V2 -> RS
A3: =RAW_GAMES!A3 -> 25/26 | B3: =RAW_GAMES!B3 -> 45909 | C3: =RAW_GAMES!E3 -> CEB | D3: =RAW_GAMES!F3 -> SPA | E3: =RAW_GAMES!G3 -> 1 | F3: =RAW_GAMES!H3 -> 2 | G3: =RAW_GAMES!I3 -> 3 | H3: =F3-G3 -> -1 | I3: =RAW_GAMES!J3 -> 28 | J3: =RAW_GAMES!K3 -> 26 | K3: =I3-J3 -> 2 | L3: =IF(RAW_GAMES!L3="","",RAW_GAMES!L3) -> 1.69 | M3: =IF(RAW_GAMES!M3="","",RAW_GAMES!M3) -> 2.3 | N3: =IF(L3="","",L3-M3) -> -0.61 | O3: =RAW_GAMES!O3 -> 3 | P3: =RAW_GAMES!N3 -> 0 | Q3: =IF(O3>0,P3/O3,0) -> 0 | R3: =RAW_GAMES!Q3 -> 2 | S3: =RAW_GAMES!P3 -> 0 | T3: =IF(R3>0, 1-(S3/R3),1) -> 1 | U3: =_xlfn.XLOOKUP(C3, CALC_TEAMS_SEASON!B:B, CALC_TEAMS_SEASON!F:F) -> 0.13021354 | V3: =_xlfn.XLOOKUP(D3, CALC_TEAMS_SEASON!B:B, CALC_TEAMS_SEASON!F:F) -> 0.2206044 | W3: =RAW_GAMES!R3 -> Strmeň | X3: =RAW_GAMES!S3 -> 23 | Y3: =IF(F3>G3,1,0) -> 0 | Z3: =RAW_GAMES!V3 -> RS
A4: =RAW_GAMES!A4 -> 25/26 | B4: =RAW_GAMES!B4 -> 45910 | C4: =RAW_GAMES!E4 -> PCE | D4: =RAW_GAMES!F4 -> MHK | E4: =RAW_GAMES!G4 -> 1 | F4: =RAW_GAMES!H4 -> 7 | G4: =RAW_GAMES!I4 -> 1 | H4: =F4-G4 -> 6 | I4: =RAW_GAMES!J4 -> 29 | J4: =RAW_GAMES!K4 -> 33 | K4: =I4-J4 -> -4 | L4: =IF(RAW_GAMES!L4="","",RAW_GAMES!L4) | M4: =IF(RAW_GAMES!M4="","",RAW_GAMES!M4) | N4: =IF(L4="","",L4-M4) | O4: =RAW_GAMES!O4 -> 6 | P4: =RAW_GAMES!N4 -> 3 | Q4: =IF(O4>0,P4/O4,0) -> 0.5 | R4: =RAW_GAMES!Q4 -> 8 | S4: =RAW_GAMES!P4 -> 0 | T4: =IF(R4>0, 1-(S4/R4),1) -> 1 | U4: =_xlfn.XLOOKUP(C4, CALC_TEAMS_SEASON!B:B, CALC_TEAMS_SEASON!F:F) -> 0.20297619 | V4: =_xlfn.XLOOKUP(D4, CALC_TEAMS_SEASON!B:B, CALC_TEAMS_SEASON!F:F) -> 0.14184982 | W4: =RAW_GAMES!R4 -> Will | X4: =RAW_GAMES!S4 -> 32 | Y4: =IF(F4>G4,1,0) -> 1 | Z4: =RAW_GAMES!V4 -> RS
A5: =RAW_GAMES!A5 -> 25/26 | B5: =RAW_GAMES!B5 -> 45910 | C5: =RAW_GAMES!E5 -> TRI | D5: =RAW_GAMES!F5 -> OLO | E5: =RAW_GAMES!G5 -> 1 | F5: =RAW_GAMES!H5 -> 8 | G5: =RAW_GAMES!I5 -> 2 | H5: =F5-G5 -> 6 | I5: =RAW_GAMES!J5 -> 38 | J5: =RAW_GAMES!K5 -> 30 | K5: =I5-J5 -> 8 | L5: =IF(RAW_GAMES!L5="","",RAW_GAMES!L5) -> 2.74 | M5: =IF(RAW_GAMES!M5="","",RAW_GAMES!M5) -> 3.24 | N5: =IF(L5="","",L5-M5) -> -0.5 | O5: =RAW_GAMES!O5 -> 4 | P5: =RAW_GAMES!N5 -> 3 | Q5: =IF(O5>0,P5/O5,0) -> 0.75 | R5: =RAW_GAMES!Q5 -> 3 | S5: =RAW_GAMES!P5 -> 0 | T5: =IF(R5>0, 1-(S5/R5),1) -> 1 | U5: =_xlfn.XLOOKUP(C5, CALC_TEAMS_SEASON!B:B, CALC_TEAMS_SEASON!F:F) -> 0.17437424 | V5: =_xlfn.XLOOKUP(D5, CALC_TEAMS_SEASON!B:B, CALC_TEAMS_SEASON!F:F) -> 0.14989316 | W5: =RAW_GAMES!R5 -> Kacetl | X5: =RAW_GAMES!S5 -> 28 | Y5: =IF(F5>G5,1,0) -> 1 | Z5: =RAW_GAMES!V5 -> RS
A6: =RAW_GAMES!A6 -> 25/26 | B6: =RAW_GAMES!B6 -> 45910 | C6: =RAW_GAMES!E6 -> KOM | D6: =RAW_GAMES!F6 -> LIT | E6: =RAW_GAMES!G6 -> 1 | F6: =RAW_GAMES!H6 -> 4 | G6: =RAW_GAMES!I6 -> 2 | H6: =F6-G6 -> 2 | I6: =RAW_GAMES!J6 -> 28 | J6: =RAW_GAMES!K6 -> 14 | K6: =I6-J6 -> 14 | L6: =IF(RAW_GAMES!L6="","",RAW_GAMES!L6) | M6: =IF(RAW_GAMES!M6="","",RAW_GAMES!M6) | N6: =IF(L6="","",L6-M6) | O6: =RAW_GAMES!O6 -> 7 | P6: =RAW_GAMES!N6 -> 0 | Q6: =IF(O6>0,P6/O6,0) -> 0 | R6: =RAW_GAMES!Q6 -> 5 | S6: =RAW_GAMES!P6 -> 1 | T6: =IF(R6>0, 1-(S6/R6),1) -> 0.8 | U6: =_xlfn.XLOOKUP(C6, CALC_TEAMS_SEASON!B:B, CALC_TEAMS_SEASON!F:F) -> 0.14358974 | V6: =_xlfn.XLOOKUP(D6, CALC_TEAMS_SEASON!B:B, CALC_TEAMS_SEASON!F:F) -> 0.10089286 | W6: =RAW_GAMES!R6 -> Stezka | X6: =RAW_GAMES!S6 -> 12 | Y6: =IF(F6>G6,1,0) -> 1 | Z6: =RAW_GAMES!V6 -> RS
A7: =RAW_GAMES!A7 -> 25/26 | B7: =RAW_GAMES!B7 -> 45910 | C7: =RAW_GAMES!E7 -> KLA | D7: =RAW_GAMES!F7 -> MBL | E7: =RAW_GAMES!G7 -> 1 | F7: =RAW_GAMES!H7 -> 1 | G7: =RAW_GAMES!I7 -> 2 | H7: =F7-G7 -> -1 | I7: =RAW_GAMES!J7 -> 28 | J7: =RAW_GAMES!K7 -> 15 | K7: =I7-J7 -> 13 | L7: =IF(RAW_GAMES!L7="","",RAW_GAMES!L7) | M7: =IF(RAW_GAMES!M7="","",RAW_GAMES!M7) | N7: =IF(L7="","",L7-M7) | O7: =RAW_GAMES!O7 -> 5 | P7: =RAW_GAMES!N7 -> 0 | Q7: =IF(O7>0,P7/O7,0) -> 0 | R7: =RAW_GAMES!Q7 -> 5 | S7: =RAW_GAMES!P7 -> 1 | T7: =IF(R7>0, 1-(S7/R7),1) -> 0.8 | U7: =_xlfn.XLOOKUP(C7, CALC_TEAMS_SEASON!B:B, CALC_TEAMS_SEASON!F:F) -> 0.13120421 | V7: =_xlfn.XLOOKUP(D7, CALC_TEAMS_SEASON!B:B, CALC_TEAMS_SEASON!F:F) -> 0.11826923 | W7: =RAW_GAMES!R7 -> Brízgala | X7: =RAW_GAMES!S7 -> 13 | Y7: =IF(F7>G7,1,0) -> 0 | Z7: =RAW_GAMES!V7 -> RS
A8: =RAW_GAMES!A8 -> 25/26 | B8: =RAW_GAMES!B8 -> 45910 | C8: =RAW_GAMES!E8 -> KVA | D8: =RAW_GAMES!F8 -> VIT | E8: =RAW_GAMES!G8 -> 1 | F8: =RAW_GAMES!H8 -> 4 | G8: =RAW_GAMES!I8 -> 7 | H8: =F8-G8 -> -3 | I8: =RAW_GAMES!J8 -> 31 | J8: =RAW_GAMES!K8 -> 24 | K8: =I8-J8 -> 7 | L8: =IF(RAW_GAMES!L8="","",RAW_GAMES!L8) | M8: =IF(RAW_GAMES!M8="","",RAW_GAMES!M8) | N8: =IF(L8="","",L8-M8) | O8: =RAW_GAMES!O8 -> 6 | P8: =RAW_GAMES!N8 -> 1 | Q8: =IF(O8>0,P8/O8,0) -> 0.16666667 | R8: =RAW_GAMES!Q8 -> 6 | S8: =RAW_GAMES!P8 -> 1 | T8: =IF(R8>0, 1-(S8/R8),1) -> 0.83333333 | U8: =_xlfn.XLOOKUP(C8, CALC_TEAMS_SEASON!B:B, CALC_TEAMS_SEASON!F:F) -> 0.17387057 | V8: =_xlfn.XLOOKUP(D8, CALC_TEAMS_SEASON!B:B, CALC_TEAMS_SEASON!F:F) -> 0.1698489 | W8: =RAW_GAMES!R8 -> Král | X8: =RAW_GAMES!S8 -> 17 | Y8: =IF(F8>G8,1,0) -> 0 | Z8: =RAW_GAMES!V8 -> RS
A9: =RAW_GAMES!A9 -> 25/26 | B9: =RAW_GAMES!B9 -> 45910 | C9: =RAW_GAMES!E9 -> LIB | D9: =RAW_GAMES!F9 -> PLZ | E9: =RAW_GAMES!G9 -> 1 | F9: =RAW_GAMES!H9 -> 1 | G9: =RAW_GAMES!I9 -> 3 | H9: =F9-G9 -> -2 | I9: =RAW_GAMES!J9 -> 24 | J9: =RAW_GAMES!K9 -> 25 | K9: =I9-J9 -> -1 | L9: =IF(RAW_GAMES!L9="","",RAW_GAMES!L9) | M9: =IF(RAW_GAMES!M9="","",RAW_GAMES!M9) | N9: =IF(L9="","",L9-M9) | O9: =RAW_GAMES!O9 -> 5 | P9: =RAW_GAMES!N9 -> 0 | Q9: =IF(O9>0,P9/O9,0) -> 0 | R9: =RAW_GAMES!Q9 -> 6 | S9: =RAW_GAMES!P9 -> 0 | T9: =IF(R9>0, 1-(S9/R9),1) -> 1 | U9: =_xlfn.XLOOKUP(C9, CALC_TEAMS_SEASON!B:B, CALC_TEAMS_SEASON!F:F) -> 0.14377289 | V9: =_xlfn.XLOOKUP(D9, CALC_TEAMS_SEASON!B:B, CALC_TEAMS_SEASON!F:F) -> 0.17641178 | W9: =RAW_GAMES!R9 -> Kváča | X9: =RAW_GAMES!S9 -> 22 | Y9: =IF(F9>G9,1,0) -> 0 | Z9: =RAW_GAMES!V9 -> RS
A10: =RAW_GAMES!A10 -> 25/26 | B10: =RAW_GAMES!B10 -> 45910 | C10: =RAW_GAMES!E10 -> LIT | D10: =RAW_GAMES!F10 -> KOM | E10: =RAW_GAMES!G10 -> 0 | F10: =RAW_GAMES!H10 -> 2 | G10: =RAW_GAMES!I10 -> 4 | H10: =F10-G10 -> -2 | I10: =RAW_GAMES!J10 -> 14 | J10: =RAW_GAMES!K10 -> 28 | K10: =I10-J10 -> -14 | L10: =IF(RAW_GAMES!L10="","",RAW_GAMES!L10) | M10: =IF(RAW_GAMES!M10="","",RAW_GAMES!M10) | N10: =IF(L10="","",L10-M10) | O10: =RAW_GAMES!O10 -> 5 | P10: =RAW_GAMES!N10 -> 1 | Q10: =IF(O10>0,P10/O10,0) -> 0.2 | R10: =RAW_GAMES!Q10 -> 7 | S10: =RAW_GAMES!P10 -> 0 | T10: =IF(R10>0, 1-(S10/R10),1) -> 1 | U10: =_xlfn.XLOOKUP(C10, CALC_TEAMS_SEASON!B:B, CALC_TEAMS_SEASON!F:F) -> 0.10089286 | V10: =_xlfn.XLOOKUP(D10, CALC_TEAMS_SEASON!B:B, CALC_TEAMS_SEASON!F:F) -> 0.14358974 | W10: =RAW_GAMES!R10 -> Tomek | X10: =RAW_GAMES!S10 -> 24 | Y10: =IF(F10>G10,1,0) -> 0 | Z10: =RAW_GAMES!V10 -> RS
A11: =RAW_GAMES!A11 -> 25/26 | B11: =RAW_GAMES!B11 -> 45910 | C11: =RAW_GAMES!E11 -> MBL | D11: =RAW_GAMES!F11 -> KLA | E11: =RAW_GAMES!G11 -> 0 | F11: =RAW_GAMES!H11 -> 2 | G11: =RAW_GAMES!I11 -> 1 | H11: =F11-G11 -> 1 | I11: =RAW_GAMES!J11 -> 15 | J11: =RAW_GAMES!K11 -> 28 | K11: =I11-J11 -> -13 | L11: =IF(RAW_GAMES!L11="","",RAW_GAMES!L11) | M11: =IF(RAW_GAMES!M11="","",RAW_GAMES!M11) | N11: =IF(L11="","",L11-M11) | O11: =RAW_GAMES!O11 -> 5 | P11: =RAW_GAMES!N11 -> 1 | Q11: =IF(O11>0,P11/O11,0) -> 0.2 | R11: =RAW_GAMES!Q11 -> 5 | S11: =RAW_GAMES!P11 -> 0 | T11: =IF(R11>0, 1-(S11/R11),1) -> 1 | U11: =_xlfn.XLOOKUP(C11, CALC_TEAMS_SEASON!B:B, CALC_TEAMS_SEASON!F:F) -> 0.11826923 | V11: =_xlfn.XLOOKUP(D11, CALC_TEAMS_SEASON!B:B, CALC_TEAMS_SEASON!F:F) -> 0.13120421 | W11: =RAW_GAMES!R11 -> Furch | X11: =RAW_GAMES!S11 -> 27 | Y11: =IF(F11>G11,1,0) -> 1 | Z11: =RAW_GAMES!V11 -> RS
A12: =RAW_GAMES!A12 -> 25/26 | B12: =RAW_GAMES!B12 -> 45910 | C12: =RAW_GAMES!E12 -> MHK | D12: =RAW_GAMES!F12 -> PCE | E12: =RAW_GAMES!G12 -> 0 | F12: =RAW_GAMES!H12 -> 1 | G12: =RAW_GAMES!I12 -> 7 | H12: =F12-G12 -> -6 | I12: =RAW_GAMES!J12 -> 33 | J12: =RAW_GAMES!K12 -> 29 | K12: =I12-J12 -> 4 | L12: =IF(RAW_GAMES!L12="","",RAW_GAMES!L12) | M12: =IF(RAW_GAMES!M12="","",RAW_GAMES!M12) | N12: =IF(L12="","",L12-M12) | O12: =RAW_GAMES!O12 -> 6 | P12: =RAW_GAMES!N12 -> 0 | Q12: =IF(O12>0,P12/O12,0) -> 0 | R12: =RAW_GAMES!Q12 -> 8 | S12: =RAW_GAMES!P12 -> 3 | T12: =IF(R12>0, 1-(S12/R12),1) -> 0.625 | U12: =_xlfn.XLOOKUP(C12, CALC_TEAMS_SEASON!B:B, CALC_TEAMS_SEASON!F:F) -> 0.14184982 | V12: =_xlfn.XLOOKUP(D12, CALC_TEAMS_SEASON!B:B, CALC_TEAMS_SEASON!F:F) -> 0.20297619 | W12: =RAW_GAMES!R12 -> Novotný | X12: =RAW_GAMES!S12 -> 26 | Y12: =IF(F12>G12,1,0) -> 0 | Z12: =RAW_GAMES!V12 -> RS
A13: =RAW_GAMES!A13 -> 25/26 | B13: =RAW_GAMES!B13 -> 45910 | C13: =RAW_GAMES!E13 -> OLO | D13: =RAW_GAMES!F13 -> TRI | E13: =RAW_GAMES!G13 -> 0 | F13: =RAW_GAMES!H13 -> 2 | G13: =RAW_GAMES!I13 -> 8 | H13: =F13-G13 -> -6 | I13: =RAW_GAMES!J13 -> 30 | J13: =RAW_GAMES!K13 -> 38 | K13: =I13-J13 -> -8 | L13: =IF(RAW_GAMES!L13="","",RAW_GAMES!L13) -> 3.24 | M13: =IF(RAW_GAMES!M13="","",RAW_GAMES!M13) -> 2.74 | N13: =IF(L13="","",L13-M13) -> 0.5 | O13: =RAW_GAMES!O13 -> 3 | P13: =RAW_GAMES!N13 -> 0 | Q13: =IF(O13>0,P13/O13,0) -> 0 | R13: =RAW_GAMES!Q13 -> 4 | S13: =RAW_GAMES!P13 -> 3 | T13: =IF(R13>0, 1-(S13/R13),1) -> 0.25 | U13: =_xlfn.XLOOKUP(C13, CALC_TEAMS_SEASON!B:B, CALC_TEAMS_SEASON!F:F) -> 0.14989316 | V13: =_xlfn.XLOOKUP(D13, CALC_TEAMS_SEASON!B:B, CALC_TEAMS_SEASON!F:F) -> 0.17437424 | W13: =RAW_GAMES!R13 -> Machovský | X13: =RAW_GAMES!S13 -> 30 | Y13: =IF(F13>G13,1,0) -> 0 | Z13: =RAW_GAMES!V13 -> RS
... A731: =RAW_GAMES!A731 -> 26/27 | B731: =RAW_GAMES!B731 -> 46160 | C731: =RAW_GAMES!E731 -> KOM | D731: =RAW_GAMES!F731 -> PCE | E731: =RAW_GAMES!G731 -> 0 | F731: =RAW_GAMES!H731 -> 0 | G731: =RAW_GAMES!I731 -> 0 | H731: =F731-G731 -> 0 | I731: =RAW_GAMES!J731 -> 0 | J731: =RAW_GAMES!K731 -> 0 | K731: =I731-J731 -> 0 | L731: =IF(RAW_GAMES!L731="","",RAW_GAMES!L731) | M731: =IF(RAW_GAMES!M731="","",RAW_GAMES!M731) | N731: =IF(L731="","",L731-M731) | O731: =RAW_GAMES!O731 -> 0 | P731: =RAW_GAMES!N731 -> 0 | Q731: =IF(O731>0,P731/O731,0) -> 0 | R731: =RAW_GAMES!Q731 -> 0 | S731: =RAW_GAMES!P731 -> 0 | T731: =IF(R731>0, 1-(S731/R731),1) -> 1 | U731: =_xlfn.XLOOKUP(C731, CALC_TEAMS_SEASON!B:B, CALC_TEAMS_SEASON!F:F) -> 0.14358974 | V731: =_xlfn.XLOOKUP(D731, CALC_TEAMS_SEASON!B:B, CALC_TEAMS_SEASON!F:F) -> 0.20297619 | W731: =RAW_GAMES!R731 -> Stezka | X731: =RAW_GAMES!S731 -> 0 | Y731: =IF(F731>G731,1,0) -> 0 | Z731: =RAW_GAMES!V731 -> RS

Sheet CALC_GOALIES
A1: Season | B1: Goalie | C1: Team | D1: Games | E1: Shots_against | F1: Goals_Against | G1: SV_Season_% | H1: SV_Last5 | I1: GSAA_Proxy | J1: GSAA_5G | K1: Goalie_rating | L1: Shots_Last5 | M1: Goals_last5 | N1: Game_Type
A2: 25/26 | B2: Malík | C2: =_xlfn.XLOOKUP(B2,RAW_GAMES!R:R,RAW_GAMES!E:E) -> PLZ | D2: =COUNTIFS(RAW_GAMES!R:R,B2,RAW_GAMES!V:V,CALC_GOALIES!N16) -> 38 | E2: =SUMIFS(RAW_GAMES!K:K,RAW_GAMES!R:R,B2,RAW_GAMES!V:V,N2) -> 905 | F2: =SUMIFS(RAW_GAMES!I:I,RAW_GAMES!R:R,B2,RAW_GAMES!V:V,N2) -> 68 | G2: =1-(F2/E2) -> 0.92486188 | H2: =AVERAGEIFS(CALC_GOALIES_FORM!I:I,CALC_GOALIES_FORM!D:D,CALC_GOALIES!B16,CALC_GOALIES_FORM!A:A,CALC_GOALIES!A16) -> 0.92102205 | I2: =(G2-0.915)*E2 -> 8.925 | J2: =(L2*(1-CALC_GOALIES_FORM!$R$1))-M2 -> 2.0060293 | K2: =G2-CALC_GOALIES_FORM!$R$1 -> 0.01761704 | L2: =SUMIFS(CALC_GOALIES_FORM!F:F,CALC_GOALIES_FORM!D:D,CALC_GOALIES!B16,CALC_GOALIES_FORM!A:A,CALC_GOALIES!A16) -> 151 | M2: =SUMIFS(CALC_GOALIES_FORM!H:H,CALC_GOALIES_FORM!D:D,CALC_GOALIES!B16,CALC_GOALIES_FORM!A:A,CALC_GOALIES!A16) -> 12 | N2: RS
A3: 25/26 | B3: Škorvánek | C3: =_xlfn.XLOOKUP(B3,RAW_GAMES!R:R,RAW_GAMES!E:E) -> MHK | D3: =COUNTIFS(RAW_GAMES!R:R,B3,RAW_GAMES!V:V,CALC_GOALIES!N14) -> 41 | E3: =SUMIFS(RAW_GAMES!K:K,RAW_GAMES!R:R,B3,RAW_GAMES!V:V,N3) -> 1087 | F3: =SUMIFS(RAW_GAMES!I:I,RAW_GAMES!R:R,B3,RAW_GAMES!V:V,N3) -> 77 | G3: =1-(F3/E3) -> 0.92916283 | H3: =AVERAGEIFS(CALC_GOALIES_FORM!I:I,CALC_GOALIES_FORM!D:D,CALC_GOALIES!B14,CALC_GOALIES_FORM!A:A,CALC_GOALIES!A14) -> 0.87025058 | I3: =(G3-0.915)*E3 -> 15.395 | J3: =(L3*(1-CALC_GOALIES_FORM!$R$1))-M3 -> -3.9418291 | K3: =G3-CALC_GOALIES_FORM!$R$1 -> 0.021917995 | L3: =SUMIFS(CALC_GOALIES_FORM!F:F,CALC_GOALIES_FORM!D:D,CALC_GOALIES!B14,CALC_GOALIES_FORM!A:A,CALC_GOALIES!A14) -> 130 | M3: =SUMIFS(CALC_GOALIES_FORM!H:H,CALC_GOALIES_FORM!D:D,CALC_GOALIES!B14,CALC_GOALIES_FORM!A:A,CALC_GOALIES!A14) -> 16 | N3: RS
A4: 25/26 | B4: Mazanec | C4: =_xlfn.XLOOKUP(B4,RAW_GAMES!R:R,RAW_GAMES!E:E) -> TRI | D4: =COUNTIFS(RAW_GAMES!R:R,B4,RAW_GAMES!V:V,CALC_GOALIES!N5) -> 38 | E4: =SUMIFS(RAW_GAMES!K:K,RAW_GAMES!R:R,B4,RAW_GAMES!V:V,N4) -> 1050 | F4: =SUMIFS(RAW_GAMES!I:I,RAW_GAMES!R:R,B4,RAW_GAMES!V:V,N4) -> 83 | G4: =1-(F4/E4) -> 0.92095238 | H4: =AVERAGEIFS(CALC_GOALIES_FORM!I:I,CALC_GOALIES_FORM!D:D,CALC_GOALIES!B5,CALC_GOALIES_FORM!A:A,CALC_GOALIES!A5) -> 0.90087652 | I4: =(G4-0.915)*E4 -> 6.25 | J4: =(L4*(1-CALC_GOALIES_FORM!$R$1))-M4 -> -0.59111518 | K4: =G4-CALC_GOALIES_FORM!$R$1 -> 0.013707542 | L4: =SUMIFS(CALC_GOALIES_FORM!F:F,CALC_GOALIES_FORM!D:D,CALC_GOALIES!B5,CALC_GOALIES_FORM!A:A,CALC_GOALIES!A5) -> 123 | M4: =SUMIFS(CALC_GOALIES_FORM!H:H,CALC_GOALIES_FORM!D:D,CALC_GOALIES!B5,CALC_GOALIES_FORM!A:A,CALC_GOALIES!A5) -> 12 | N4: RS
A5: 25/26 | B5: Kváča | C5: =_xlfn.XLOOKUP(B5,RAW_GAMES!R:R,RAW_GAMES!E:E) -> LIB | D5: =COUNTIFS(RAW_GAMES!R:R,B5,RAW_GAMES!V:V,CALC_GOALIES!N11) -> 42 | E5: =SUMIFS(RAW_GAMES!K:K,RAW_GAMES!R:R,B5,RAW_GAMES!V:V,N5) -> 1168 | F5: =SUMIFS(RAW_GAMES!I:I,RAW_GAMES!R:R,B5,RAW_GAMES!V:V,N5) -> 94 | G5: =1-(F5/E5) -> 0.91952055 | H5: =AVERAGEIFS(CALC_GOALIES_FORM!I:I,CALC_GOALIES_FORM!D:D,CALC_GOALIES!B11,CALC_GOALIES_FORM!A:A,CALC_GOALIES!A11) -> 0.91326346 | I5: =(G5-0.915)*E5 -> 5.28 | J5: =(L5*(1-CALC_GOALIES_FORM!$R$1))-M5 -> 0.26398804 | K5: =G5-CALC_GOALIES_FORM!$R$1 -> 0.012275709 | L5: =SUMIFS(CALC_GOALIES_FORM!F:F,CALC_GOALIES_FORM!D:D,CALC_GOALIES!B11,CALC_GOALIES_FORM!A:A,CALC_GOALIES!A11) -> 143 | M5: =SUMIFS(CALC_GOALIES_FORM!H:H,CALC_GOALIES_FORM!D:D,CALC_GOALIES!B11,CALC_GOALIES_FORM!A:A,CALC_GOALIES!A11) -> 13 | N5: RS
A6: 25/26 | B6: Mokry | C6: =_xlfn.XLOOKUP(B6,RAW_GAMES!R:R,RAW_GAMES!E:E) -> MBL | D6: =COUNTIFS(RAW_GAMES!R:R,B6,RAW_GAMES!V:V,CALC_GOALIES!N28) -> 11 | E6: =SUMIFS(RAW_GAMES!K:K,RAW_GAMES!R:R,B6,RAW_GAMES!V:V,N6) -> 367 | F6: =SUMIFS(RAW_GAMES!I:I,RAW_GAMES!R:R,B6,RAW_GAMES!V:V,N6) -> 27 | G6: =1-(F6/E6) -> 0.92643052 | H6: =AVERAGEIFS(CALC_GOALIES_FORM!I:I,CALC_GOALIES_FORM!D:D,CALC_GOALIES!B28,CALC_GOALIES_FORM!A:A,CALC_GOALIES!A28) -> 0.86475064 | I6: =(G6-0.915)*E6 -> 4.195 | J6: =(L6*(1-CALC_GOALIES_FORM!$R$1))-M6 -> -6.2519294 | K6: =G6-CALC_GOALIES_FORM!$R$1 -> 0.019185679 | L6: =SUMIFS(CALC_GOALIES_FORM!F:F,CALC_GOALIES_FORM!D:D,CALC_GOALIES!B28,CALC_GOALIES_FORM!A:A,CALC_GOALIES!A28) -> 159 | M6: =SUMIFS(CALC_GOALIES_FORM!H:H,CALC_GOALIES_FORM!D:D,CALC_GOALIES!B28,CALC_GOALIES_FORM!A:A,CALC_GOALIES!A28) -> 21 | N6: RS
A7: 25/26 | B7: Will | C7: =_xlfn.XLOOKUP(B7,RAW_GAMES!R:R,RAW_GAMES!E:E) -> PCE | D7: =COUNTIFS(RAW_GAMES!R:R,B7,RAW_GAMES!V:V,CALC_GOALIES!N2) -> 38 | E7: =SUMIFS(RAW_GAMES!K:K,RAW_GAMES!R:R,B7,RAW_GAMES!V:V,N7) -> 862 | F7: =SUMIFS(RAW_GAMES!I:I,RAW_GAMES!R:R,B7,RAW_GAMES!V:V,N7) -> 76 | G7: =1-(F7/E7) -> 0.91183295 | H7: =AVERAGEIFS(CALC_GOALIES_FORM!I:I,CALC_GOALIES_FORM!D:D,CALC_GOALIES!B2,CALC_GOALIES_FORM!A:A,CALC_GOALIES!A2) -> 0.91510695 | I7: =(G7-0.915)*E7 -> -2.73 | J7: =(L7*(1-CALC_GOALIES_FORM!$R$1))-M7 -> 2.3682713 | K7: =G7-CALC_GOALIES_FORM!$R$1 -> 0.0045881077 | L7: =SUMIFS(CALC_GOALIES_FORM!F:F,CALC_GOALIES_FORM!D:D,CALC_GOALIES!B2,CALC_GOALIES_FORM!A:A,CALC_GOALIES!A2) -> 101 | M7: =SUMIFS(CALC_GOALIES_FORM!H:H,CALC_GOALIES_FORM!D:D,CALC_GOALIES!B2,CALC_GOALIES_FORM!A:A,CALC_GOALIES!A2) -> 7 | N7: RS
A8: 25/26 | B8: Brízgala | C8: =_xlfn.XLOOKUP(B8,RAW_GAMES!R:R,RAW_GAMES!E:E) -> KLA | D8: =COUNTIFS(RAW_GAMES!R:R,B8,RAW_GAMES!V:V,CALC_GOALIES!N20) -> 38 | E8: =SUMIFS(RAW_GAMES!K:K,RAW_GAMES!R:R,B8,RAW_GAMES!V:V,N8) -> 1096 | F8: =SUMIFS(RAW_GAMES!I:I,RAW_GAMES!R:R,B8,RAW_GAMES!V:V,N8) -> 88 | G8: =1-(F8/E8) -> 0.91970803 | H8: =AVERAGEIFS(CALC_GOALIES_FORM!I:I,CALC_GOALIES_FORM!D:D,CALC_GOALIES!B20,CALC_GOALIES_FORM!A:A,CALC_GOALIES!A20) -> 0.88700818 | I8: =(G8-0.915)*E8 -> 5.16 | J8: =(L8*(1-CALC_GOALIES_FORM!$R$1))-M8 -> -1.7157052 | K8: =G8-CALC_GOALIES_FORM!$R$1 -> 0.01246319 | L8: =SUMIFS(CALC_GOALIES_FORM!F:F,CALC_GOALIES_FORM!D:D,CALC_GOALIES!B20,CALC_GOALIES_FORM!A:A,CALC_GOALIES!A20) -> 154 | M8: =SUMIFS(CALC_GOALIES_FORM!H:H,CALC_GOALIES_FORM!D:D,CALC_GOALIES!B20,CALC_GOALIES_FORM!A:A,CALC_GOALIES!A20) -> 16 | N8: RS
A9: 25/26 | B9: Michajlov | C9: =_xlfn.XLOOKUP(B9,RAW_GAMES!R:R,RAW_GAMES!E:E) -> SPA | D9: =COUNTIFS(RAW_GAMES!R:R,B9,RAW_GAMES!V:V,CALC_GOALIES!N24) -> 4 | E9: =SUMIFS(RAW_GAMES!K:K,RAW_GAMES!R:R,B9,RAW_GAMES!V:V,N9) -> 101 | F9: =SUMIFS(RAW_GAMES!I:I,RAW_GAMES!R:R,B9,RAW_GAMES!V:V,N9) -> 9 | G9: =1-(F9/E9) -> 0.91089109 | H9: =AVERAGEIFS(CALC_GOALIES_FORM!I:I,CALC_GOALIES_FORM!D:D,CALC_GOALIES!B24,CALC_GOALIES_FORM!A:A,CALC_GOALIES!A24) -> 0.87847752 | I9: =(G9-0.915)*E9 -> -0.415 | J9: =(L9*(1-CALC_GOALIES_FORM!$R$1))-M9 -> -3.1273394 | K9: =G9-CALC_GOALIES_FORM!$R$1 -> 0.0036462502 | L9: =SUMIFS(CALC_GOALIES_FORM!F:F,CALC_GOALIES_FORM!D:D,CALC_GOALIES!B24,CALC_GOALIES_FORM!A:A,CALC_GOALIES!A24) -> 128 | M9: =SUMIFS(CALC_GOALIES_FORM!H:H,CALC_GOALIES_FORM!D:D,CALC_GOALIES!B24,CALC_GOALIES_FORM!A:A,CALC_GOALIES!A24) -> 15 | N9: RS
A10: 25/26 | B10: Vomáčka | C10: =_xlfn.XLOOKUP(B10,RAW_GAMES!R:R,RAW_GAMES!E:E) -> PCE | D10: =COUNTIFS(RAW_GAMES!R:R,B10,RAW_GAMES!V:V,CALC_GOALIES!N3) -> 6 | E10: =SUMIFS(RAW_GAMES!K:K,RAW_GAMES!R:R,B10,RAW_GAMES!V:V,N10) -> 189 | F10: =SUMIFS(RAW_GAMES!I:I,RAW_GAMES!R:R,B10,RAW_GAMES!V:V,N10) -> 18 | G10: =1-(F10/E10) -> 0.9047619 | H10: =AVERAGEIFS(CALC_GOALIES_FORM!I:I,CALC_GOALIES_FORM!D:D,CALC_GOALIES!B3,CALC_GOALIES_FORM!A:A,CALC_GOALIES!A3) -> 0.93529258 | I10: =(G10-0.915)*E10 -> -1.935 | J10: =(L10*(1-CALC_GOALIES_FORM!$R$1))-M10 -> 4.0060293 | K10: =G10-CALC_GOALIES_FORM!$R$1 -> -0.0024829341 | L10: =SUMIFS(CALC_GOALIES_FORM!F:F,CALC_GOALIES_FORM!D:D,CALC_GOALIES!B3,CALC_GOALIES_FORM!A:A,CALC_GOALIES!A3) -> 151 | M10: =SUMIFS(CALC_GOALIES_FORM!H:H,CALC_GOALIES_FORM!D:D,CALC_GOALIES!B3,CALC_GOALIES_FORM!A:A,CALC_GOALIES!A3) -> 10 | N10: RS
A11: 25/26 | B11: Klouček | C11: =_xlfn.XLOOKUP(B11,RAW_GAMES!R:R,RAW_GAMES!E:E) -> CEB | D11: =COUNTIFS(RAW_GAMES!R:R,B11,RAW_GAMES!V:V,CALC_GOALIES!N7) -> 24 | E11: =SUMIFS(RAW_GAMES!K:K,RAW_GAMES!R:R,B11,RAW_GAMES!V:V,N11) -> 653 | F11: =SUMIFS(RAW_GAMES!I:I,RAW_GAMES!R:R,B11,RAW_GAMES!V:V,N11) -> 58 | G11: =1-(F11/E11) -> 0.91117917 | H11: =AVERAGEIFS(CALC_GOALIES_FORM!I:I,CALC_GOALIES_FORM!D:D,CALC_GOALIES!B7,CALC_GOALIES_FORM!A:A,CALC_GOALIES!A7) -> 0.89084904 | I11: =(G11-0.915)*E11 -> -2.495 | J11: =(L11*(1-CALC_GOALIES_FORM!$R$1))-M11 -> -1.0751978 | K11: =G11-CALC_GOALIES_FORM!$R$1 -> 0.0039343342 | L11: =SUMIFS(CALC_GOALIES_FORM!F:F,CALC_GOALIES_FORM!D:D,CALC_GOALIES!B7,CALC_GOALIES_FORM!A:A,CALC_GOALIES!A7) -> 107 | M11: =SUMIFS(CALC_GOALIES_FORM!H:H,CALC_GOALIES_FORM!D:D,CALC_GOALIES!B7,CALC_GOALIES_FORM!A:A,CALC_GOALIES!A7) -> 11 | N11: RS
A12: 25/26 | B12: Machovský | C12: =_xlfn.XLOOKUP(B12,RAW_GAMES!R:R,RAW_GAMES!E:E) -> OLO | D12: =COUNTIFS(RAW_GAMES!R:R,B12,RAW_GAMES!V:V,CALC_GOALIES!N18) -> 38 | E12: =SUMIFS(RAW_GAMES!K:K,RAW_GAMES!R:R,B12,RAW_GAMES!V:V,N12) -> 1212 | F12: =SUMIFS(RAW_GAMES!I:I,RAW_GAMES!R:R,B12,RAW_GAMES!V:V,N12) -> 107 | G12: =1-(F12/E12) -> 0.91171617 | H12: =AVERAGEIFS(CALC_GOALIES_FORM!I:I,CALC_GOALIES_FORM!D:D,CALC_GOALIES!B18,CALC_GOALIES_FORM!A:A,CALC_GOALIES!A18) -> 0.86507771 | I12: =(G12-0.915)*E12 -> -3.98 | J12: =(L12*(1-CALC_GOALIES_FORM!$R$1))-M12 -> -6.1070326 | K12: =G12-CALC_GOALIES_FORM!$R$1 -> 0.0044713327 | L12: =SUMIFS(CALC_GOALIES_FORM!F:F,CALC_GOALIES_FORM!D:D,CALC_GOALIES!B18,CALC_GOALIES_FORM!A:A,CALC_GOALIES!A18) -> 139 | M12: =SUMIFS(CALC_GOALIES_FORM!H:H,CALC_GOALIES_FORM!D:D,CALC_GOALIES!B18,CALC_GOALIES_FORM!A:A,CALC_GOALIES!A18) -> 19 | N12: RS
A13: 25/26 | B13: Subban | C13: =_xlfn.XLOOKUP(B13,RAW_GAMES!R:R,RAW_GAMES!E:E) -> PCE | D13: =COUNTIFS(RAW_GAMES!R:R,B13,RAW_GAMES!V:V,CALC_GOALIES!N4) -> 9 | E13: =SUMIFS(RAW_GAMES!K:K,RAW_GAMES!R:R,B13,RAW_GAMES!V:V,N13) -> 221 | F13: =SUMIFS(RAW_GAMES!I:I,RAW_GAMES!R:R,B13,RAW_GAMES!V:V,N13) -> 22 | G13: =1-(F13/E13) -> 0.90045249 | H13: =AVERAGEIFS(CALC_GOALIES_FORM!I:I,CALC_GOALIES_FORM!D:D,CALC_GOALIES!B4,CALC_GOALIES_FORM!A:A,CALC_GOALIES!A4) -> 0.91373754 | I13: =(G13-0.915)*E13 -> -3.215 | J13: =(L13*(1-CALC_GOALIES_FORM!$R$1))-M13 -> 0.40888482 | K13: =G13-CALC_GOALIES_FORM!$R$1 -> -0.0067923502 | L13: =SUMIFS(CALC_GOALIES_FORM!F:F,CALC_GOALIES_FORM!D:D,CALC_GOALIES!B4,CALC_GOALIES_FORM!A:A,CALC_GOALIES!A4) -> 123 | M13: =SUMIFS(CALC_GOALIES_FORM!H:H,CALC_GOALIES_FORM!D:D,CALC_GOALIES!B4,CALC_GOALIES_FORM!A:A,CALC_GOALIES!A4) -> 11 | N13: RS
A14: 25/26 | B14: Růžička | C14: =_xlfn.XLOOKUP(B14,RAW_GAMES!R:R,RAW_GAMES!E:E) -> PLZ | D14: =COUNTIFS(RAW_GAMES!R:R,B14,RAW_GAMES!V:V,CALC_GOALIES!N17) -> 14 | E14: =SUMIFS(RAW_GAMES!K:K,RAW_GAMES!R:R,B14,RAW_GAMES!V:V,N14) -> 382 | F14: =SUMIFS(RAW_GAMES!I:I,RAW_GAMES!R:R,B14,RAW_GAMES!V:V,N14) -> 36 | G14: =1-(F14/E14) -> 0.90575916 | H14: =AVERAGEIFS(CALC_GOALIES_FORM!I:I,CALC_GOALIES_FORM!D:D,CALC_GOALIES!B17,CALC_GOALIES_FORM!A:A,CALC_GOALIES!A17) -> 0.85869565 | I14: =(G14-0.915)*E14 -> -3.53 | J14: =(L14*(1-CALC_GOALIES_FORM!$R$1))-M14 -> -1.5998939 | K14: =G14-CALC_GOALIES_FORM!$R$1 -> -0.0014856766 | L14: =SUMIFS(CALC_GOALIES_FORM!F:F,CALC_GOALIES_FORM!D:D,CALC_GOALIES!B17,CALC_GOALIES_FORM!A:A,CALC_GOALIES!A17) -> 69 | M14: =SUMIFS(CALC_GOALIES_FORM!H:H,CALC_GOALIES_FORM!D:D,CALC_GOALIES!B17,CALC_GOALIES_FORM!A:A,CALC_GOALIES!A17) -> 8 | N14: RS
A15: 25/26 | B15: Frodl | C15: =_xlfn.XLOOKUP(B15,RAW_GAMES!R:R,RAW_GAMES!E:E) -> KVA | D15: =COUNTIFS(RAW_GAMES!R:R,B15,RAW_GAMES!V:V,CALC_GOALIES!N35) -> 39 | E15: =SUMIFS(RAW_GAMES!K:K,RAW_GAMES!R:R,B15,RAW_GAMES!V:V,N15) -> 1093 | F15: =SUMIFS(RAW_GAMES!I:I,RAW_GAMES!R:R,B15,RAW_GAMES!V:V,N15) -> 88 | G15: =1-(F15/E15) -> 0.91948765 | H15: =AVERAGEIFS(CALC_GOALIES_FORM!I:I,CALC_GOALIES_FORM!D:D,CALC_GOALIES!B35,CALC_GOALIES_FORM!A:A,CALC_GOALIES!A35) -> 0.80645161 | I15: =(G15-0.915)*E15 -> 4.905 | J15: =(L15*(1-CALC_GOALIES_FORM!$R$1))-M15 -> -3.12459 | K15: =G15-CALC_GOALIES_FORM!$R$1 -> 0.01224281 | L15: =SUMIFS(CALC_GOALIES_FORM!F:F,CALC_GOALIES_FORM!D:D,CALC_GOALIES!B35,CALC_GOALIES_FORM!A:A,CALC_GOALIES!A35) -> 31 | M15: =SUMIFS(CALC_GOALIES_FORM!H:H,CALC_GOALIES_FORM!D:D,CALC_GOALIES!B35,CALC_GOALIES_FORM!A:A,CALC_GOALIES!A35) -> 6 | N15: RS
A16: 25/26 | B16: Kovář | C16: =_xlfn.XLOOKUP(B16,RAW_GAMES!R:R,RAW_GAMES!E:E) -> SPA | D16: =COUNTIFS(RAW_GAMES!R:R,B16,RAW_GAMES!V:V,CALC_GOALIES!N22) -> 25 | E16: =SUMIFS(RAW_GAMES!K:K,RAW_GAMES!R:R,B16,RAW_GAMES!V:V,N16) -> 729 | F16: =SUMIFS(RAW_GAMES!I:I,RAW_GAMES!R:R,B16,RAW_GAMES!V:V,N16) -> 65 | G16: =1-(F16/E16) -> 0.91083676 | H16: =AVERAGEIFS(CALC_GOALIES_FORM!I:I,CALC_GOALIES_FORM!D:D,CALC_GOALIES!B22,CALC_GOALIES_FORM!A:A,CALC_GOALIES!A22) -> 0.86633099 | I16: =(G16-0.915)*E16 -> -3.035 | J16: =(L16*(1-CALC_GOALIES_FORM!$R$1))-M16 -> -5.8287671 | K16: =G16-CALC_GOALIES_FORM!$R$1 -> 0.0035919238 | L16: =SUMIFS(CALC_GOALIES_FORM!F:F,CALC_GOALIES_FORM!D:D,CALC_GOALIES!B22,CALC_GOALIES_FORM!A:A,CALC_GOALIES!A22) -> 142 | M16: =SUMIFS(CALC_GOALIES_FORM!H:H,CALC_GOALIES_FORM!D:D,CALC_GOALIES!B22,CALC_GOALIES_FORM!A:A,CALC_GOALIES!A22) -> 19 | N16: RS
A17: 25/26 | B17: Hamalčík | C17: =_xlfn.XLOOKUP(B17,RAW_GAMES!R:R,RAW_GAMES!E:E) -> LIB | D17: =COUNTIFS(RAW_GAMES!R:R,B17,RAW_GAMES!V:V,CALC_GOALIES!N13) -> 3 | E17: =SUMIFS(RAW_GAMES!K:K,RAW_GAMES!R:R,B17,RAW_GAMES!V:V,N17) -> 69 | F17: =SUMIFS(RAW_GAMES!I:I,RAW_GAMES!R:R,B17,RAW_GAMES!V:V,N17) -> 8 | G17: =1-(F17/E17) -> 0.88405797 | H17: =AVERAGEIFS(CALC_GOALIES_FORM!I:I,CALC_GOALIES_FORM!D:D,CALC_GOALIES!B13,CALC_GOALIES_FORM!A:A,CALC_GOALIES!A13) -> 0.93417308 | I17: =(G17-0.915)*E17 -> -2.135 | J17: =(L17*(1-CALC_GOALIES_FORM!$R$1))-M17 -> 3.6147019 | K17: =G17-CALC_GOALIES_FORM!$R$1 -> -0.023186868 | L17: =SUMIFS(CALC_GOALIES_FORM!F:F,CALC_GOALIES_FORM!D:D,CALC_GOALIES!B13,CALC_GOALIES_FORM!A:A,CALC_GOALIES!A13) -> 136 | M17: =SUMIFS(CALC_GOALIES_FORM!H:H,CALC_GOALIES_FORM!D:D,CALC_GOALIES!B13,CALC_GOALIES_FORM!A:A,CALC_GOALIES!A13) -> 9 | N17: RS
A18: 25/26 | B18: Strmeň | C18: =_xlfn.XLOOKUP(B18,RAW_GAMES!R:R,RAW_GAMES!E:E) -> CEB | D18: =COUNTIFS(RAW_GAMES!R:R,B18,RAW_GAMES!V:V,CALC_GOALIES!N8) -> 15 | E18: =SUMIFS(RAW_GAMES!K:K,RAW_GAMES!R:R,B18,RAW_GAMES!V:V,N18) -> 432 | F18: =SUMIFS(RAW_GAMES!I:I,RAW_GAMES!R:R,B18,RAW_GAMES!V:V,N18) -> 46 | G18: =1-(F18/E18) -> 0.89351852 | H18: =AVERAGEIFS(CALC_GOALIES_FORM!I:I,CALC_GOALIES_FORM!D:D,CALC_GOALIES!B8,CALC_GOALIES_FORM!A:A,CALC_GOALIES!A8) -> 0.92212445 | I18: =(G18-0.915)*E18 -> -9.28 | J18: =(L18*(1-CALC_GOALIES_FORM!$R$1))-M18 -> 2.1306193 | K18: =G18-CALC_GOALIES_FORM!$R$1 -> -0.01372632 | L18: =SUMIFS(CALC_GOALIES_FORM!F:F,CALC_GOALIES_FORM!D:D,CALC_GOALIES!B8,CALC_GOALIES_FORM!A:A,CALC_GOALIES!A8) -> 120 | M18: =SUMIFS(CALC_GOALIES_FORM!H:H,CALC_GOALIES_FORM!D:D,CALC_GOALIES!B8,CALC_GOALIES_FORM!A:A,CALC_GOALIES!A8) -> 9 | N18: RS
A19: 25/26 | B19: Soukup | C19: =_xlfn.XLOOKUP(B19,RAW_GAMES!R:R,RAW_GAMES!E:E) -> MHK | D19: =COUNTIFS(RAW_GAMES!R:R,B19,RAW_GAMES!V:V,CALC_GOALIES!N29) -> 2 | E19: =SUMIFS(RAW_GAMES!K:K,RAW_GAMES!R:R,B19,RAW_GAMES!V:V,N19) -> 62 | F19: =SUMIFS(RAW_GAMES!I:I,RAW_GAMES!R:R,B19,RAW_GAMES!V:V,N19) -> 6 | G19: =1-(F19/E19) -> 0.90322581 | H19: =AVERAGEIFS(CALC_GOALIES_FORM!I:I,CALC_GOALIES_FORM!D:D,CALC_GOALIES!B29,CALC_GOALIES_FORM!A:A,CALC_GOALIES!A29) -> 0.90598549 | I19: =(G19-0.915)*E19 -> -0.73 | J19: =(L19*(1-CALC_GOALIES_FORM!$R$1))-M19 -> -0.60264326 | K19: =G19-CALC_GOALIES_FORM!$R$1 -> -0.0040190324 | L19: =SUMIFS(CALC_GOALIES_FORM!F:F,CALC_GOALIES_FORM!D:D,CALC_GOALIES!B29,CALC_GOALIES_FORM!A:A,CALC_GOALIES!A29) -> 166 | M19: =SUMIFS(CALC_GOALIES_FORM!H:H,CALC_GOALIES_FORM!D:D,CALC_GOALIES!B29,CALC_GOALIES_FORM!A:A,CALC_GOALIES!A29) -> 16 | N19: RS
